<?xml version="1.0" encoding="utf-8"?>
<!-- This URDF was automatically created by SolidWorks to URDF Exporter! Originally created by Stephen Brawner (brawner@gmail.com) 
     Commit Version: 1.6.0-4-g7f85cfe  Build Version: 1.6.7995.38578
     For more information, please see http://wiki.ros.org/sw_urdf_exporter -->
<robot
  name="huron_description_2">
  
  <gazebo>
    <self_collide>1</self_collide>
  </gazebo>

  <link name="base_footprint" />
  <link
    name="base_link">
    <inertial>
      <origin
        xyz="4.73188960237181E-09 5.43380156814433E-07 0.0269746723866842"
        rpy="0 0 0" />
      <mass
        value="3.40723570208261" />
      <inertia
        ixx="0.00319004496846458"
        ixy="7.14900268581691E-11"
        ixz="6.0312906921393E-11"
        iyy="0.0105312204112697"
        iyz="6.92595211690858E-09"
        izz="0.0123154567422159" />
    </inertial>
    <visual>
      <origin
        xyz="0 0 0"
        rpy="0 0 0" />
      <geometry>
        <mesh
          filename="package://huron_description_2/meshes/base_link.STL" />
      </geometry>
      <material
        name="">
        <color
          rgba="0.752941176470588 0.752941176470588 0.752941176470588 1" />
      </material>
    </visual>
    <collision>
      <origin
        xyz="0 0 0"
        rpy="0 0 0" />
      <geometry>
        <mesh
          filename="package://huron_description_2/meshes/base_link.STL" />
      </geometry>
    </collision>
  </link>
  <joint name="base_joint" type="fixed">
    <parent link="base_footprint"/>
    <child link="base_link"/>
    <!-- <origin xyz="0.0 0.0 0.0" rpy="0 0 0"/> -->
    <origin xyz="0.0 0.0 1.3" rpy="0 0 0"/>
  </joint>
  <link
    name="left_upper_thigh">
    <inertial>
      <origin
        xyz="0.00063027145118244 0.000538669833131833 0.0816280399810376"
        rpy="0 0 0" />
      <mass
        value="1.6968456216795" />
      <inertia
        ixx="0.00227022630391094"
        ixy="-2.54431260104897E-06"
        ixz="-6.64622684424124E-06"
        iyy="0.00267462162343889"
        iyz="-4.69650413333908E-08"
        izz="0.00123800916526073" />
    </inertial>
    <visual>
      <origin
        xyz="0 0 0"
        rpy="0 0 0" />
      <geometry>
        <mesh
          filename="package://huron_description_2/meshes/left_upper_thigh.STL" />
      </geometry>
      <material
        name="">
        <color
          rgba="0.752941176470588 0.752941176470588 0.752941176470588 1" />
      </material>
    </visual>
    <collision>
      <origin
        xyz="0 0 0"
        rpy="0 0 0" />
      <geometry>
        <mesh
          filename="package://huron_description_2/meshes/left_upper_thigh.STL" />
      </geometry>
    </collision>
  </link>
  <joint
    name="hip_2_left_upper_thigh"
    type="revolute">
    <origin
      xyz="-0.0775 0 0"
      rpy="3.1416 0 0" />
    <parent
      link="base_link" />
    <child
      link="left_upper_thigh" />
    <axis
      xyz="0 0 1" />
    <limit
      lower="-3.14159"
      upper="3.14159"
      effort="0"
      velocity="0" />
  </joint>
  <link
    name="left_middle_thigh">
    <inertial>
      <origin
        xyz="-0.0719622084593496 -0.00611530026086354 -6.83234131536592E-05"
        rpy="0 0 0" />
      <mass
        value="1.18837728003772" />
      <inertia
        ixx="0.000982220615924269"
        ixy="-9.86513152329328E-08"
        ixz="-3.73487671878971E-07"
        iyy="0.000970452993289274"
        iyz="9.79041445139278E-08"
        izz="0.00092365496384701" />
    </inertial>
    <visual>
      <origin
        xyz="0 0 0"
        rpy="0 0 0" />
      <geometry>
        <mesh
          filename="package://huron_description_2/meshes/left_middle_thigh.STL" />
      </geometry>
      <material
        name="">
        <color
          rgba="0.752941176470588 0.752941176470588 0.752941176470588 1" />
      </material>
    </visual>
    <collision>
      <origin
        xyz="0 0 0"
        rpy="0 0 0" />
      <geometry>
        <mesh
          filename="package://huron_description_2/meshes/left_middle_thigh.STL" />
      </geometry>
    </collision>
  </link>
  <joint
    name="left_thigh_roll"
    type="revolute">
    <origin
      xyz="0 0 0.1451242"
      rpy="1.5707963267949 0 0" />
    <parent
      link="left_upper_thigh" />
    <child
      link="left_middle_thigh" />
    <axis
      xyz="-0.00629189312904533 0 -0.999980205844522" />
    <limit
      lower="-3.14159"
      upper="3.14159"
      effort="0"
      velocity="0" />
  </joint>
  <link
    name="left_lower_thigh">
    <inertial>
      <origin
        xyz="-0.266032619495271 -0.000288212950915689 -0.0531507715646498"
        rpy="0 0 0" />
      <mass
        value="4.25435975944067" />
      <inertia
        ixx="0.00345274124785122"
        ixy="1.24869769517437E-05"
        ixz="0.00197963999643362"
        iyy="0.0100324127414557"
        iyz="3.64016409863169E-07"
        izz="0.010090241102447" />
    </inertial>
    <visual>
      <origin
        xyz="0 0 0"
        rpy="0 0 0" />
      <geometry>
        <mesh
          filename="package://huron_description_2/meshes/left_lower_thigh.STL" />
      </geometry>
      <material
        name="">
        <color
          rgba="0.752941176470588 0.752941176470588 0.752941176470588 1" />
      </material>
    </visual>
    <collision>
      <origin
        xyz="0 0 0"
        rpy="0 0 0" />
      <geometry>
        <mesh
          filename="package://huron_description_2/meshes/left_lower_thigh.STL" />
      </geometry>
      <!-- <origin -->
      <!--   xyz="-0.25 0 -0.07" -->
      <!--   rpy="0 1.97 0" /> -->
      <!-- <geometry> -->
      <!--   <cylinder length="0.5" radius="0.05" /> -->
      <!-- </geometry> -->
    </collision>
  </link>
  <joint
    name="left_thigh_pitch"
    type="revolute">
    <origin
      xyz="0 0 0"
      rpy="-1.5707963267949 0 -1.57079632679489" />
    <parent
      link="left_middle_thigh" />
    <child
      link="left_lower_thigh" />
    <axis
      xyz="0 0.0062918931290415 0.999980205844522" />
    <limit
      lower="-3.14159"
      upper="3.14159"
      effort="0"
      velocity="0" />
  </joint>
  <link
    name="left_shin">
    <inertial>
      <origin
        xyz="-0.114650881627948 -0.0200601309451988 0.000818843611288478"
        rpy="0 0 0" />
      <mass
        value="1.60581202983578" />
      <inertia
        ixx="0.00116466025324857"
        ixy="-5.06243347933369E-06"
        ixz="-2.95036730912847E-10"
        iyy="0.00754378536758175"
        iyz="-2.60872069219708E-11"
        izz="0.00773513292013865" />
    </inertial>
    <visual>
      <origin
        xyz="0 0 0"
        rpy="0 0 0" />
      <geometry>
        <mesh
          filename="package://huron_description_2/meshes/left_shin.STL" />
      </geometry>
      <material
        name="">
        <color
          rgba="0.752941176470588 0.752941176470588 0.752941176470588 1" />
      </material>
    </visual>
    <collision>
      <origin
        xyz="0 0 0"
        rpy="0 0 0" />
      <!-- <origin -->
      <!--   xyz="-0.2125 -0.0115 0" -->
      <!--   rpy="0 1.57 0" /> -->
      <geometry>
        <mesh
          filename="package://huron_description_2/meshes/left_shin.STL" />
        <!-- <cylinder length="0.43" radius="0.05" /> -->
      </geometry>
    </collision>
  </link>
  <joint
    name="left_knee"
    type="revolute">
    <origin
      xyz="-0.511278478308803 4.98941573321976E-05 -1.69789967927603E-05"
      rpy="-0.00629193464362004 0 0" />
    <parent
      link="left_lower_thigh" />
    <child
      link="left_shin" />
    <axis
      xyz="0 0 1" />
    <limit
      lower="-3.14159"
      upper="3.14159"
      effort="0"
      velocity="0" />
  </joint>
  <link
    name="left_ankle_roll_link">
    <inertial>
      <origin
        xyz="-1.23603651863702E-05 5.57268410583678E-07 0.000277899308168128"
        rpy="0 0 0" />
      <mass
        value="0.0816413455622017" />
      <inertia
        ixx="2.09931500829249E-05"
        ixy="-5.12265171426361E-07"
        ixz="-2.80748290382414E-10"
        iyy="1.03508115313432E-05"
        iyz="4.07293290858292E-12"
        izz="2.23948011263121E-05" />
    </inertial>
    <visual>
      <origin
        xyz="0 0 0"
        rpy="0 0 0" />
      <geometry>
        <mesh
          filename="package://huron_description_2/meshes/left_ankle_roll_link.STL" />
      </geometry>
      <material
        name="">
        <color
          rgba="0.898039215686275 0.917647058823529 0.929411764705882 1" />
      </material>
    </visual>
    <collision>
      <origin
        xyz="0 0 0"
        rpy="0 0 0" />
      <geometry>
        <mesh
          filename="package://huron_description_2/meshes/left_ankle_roll_link.STL" />
      </geometry>
    </collision>
  </link>
  <joint
    name="left_ankle_roll"
    type="revolute">
    <origin
      xyz="-0.425000000000015 -0.0344999999997562 0"
      rpy="1.57079632679491 0 0" />
    <parent
      link="left_shin" />
    <child
      link="left_ankle_roll_link" />
    <axis
      xyz="0 0 1" />
    <limit
      lower="-3.14159"
      upper="3.14159"
      effort="0"
      velocity="0" />
  </joint>
  <link
    name="left_foot">
    <inertial>
      <origin
        xyz="-0.027041 -0.034311 0.00083257"
        rpy="0 0 0" />
      <mass
        value="2.6907" />
      <inertia
        ixx="0.0080929"
        ixy="0.00024558"
        ixz="-5.8611E-05"
        iyy="0.0012877"
        iyz="0.0001125"
        izz="0.0070808" />
    </inertial>
    <visual>
      <origin
        xyz="0 0 0"
        rpy="0 0 0" />
      <geometry>
        <mesh
          filename="package://huron_description_2/meshes/left_foot.STL" />
      </geometry>
      <material
        name="">
        <color
          rgba="0.89804 0.91765 0.92941 1" />
      </material>
    </visual>
    <collision>
      <origin
        xyz="0 0 0"
        rpy="0 0 0" />
      <geometry>
        <mesh
          filename="package://huron_description_2/meshes/left_foot.STL" />
      </geometry>
    </collision>
  </link>
  <joint
    name="left_ankle_pitch"
    type="revolute">
    <origin
      xyz="0 0 0"
      rpy="-1.5707963267949 0 0" />
    <parent
      link="left_ankle_roll_link" />
    <child
      link="left_foot" />
    <axis
      xyz="-0.0479684947160885 0 -0.998848849183235" />
    <limit
      lower="-3.14159"
      upper="3.14159"
      effort="0"
      velocity="0" />
  </joint>
  <link
    name="right_upper_thigh">
    <inertial>
      <origin
        xyz="0 0 0"
        rpy="0 0 0" />
      <mass
        value="1.6968" />
      <inertia
        ixx="0.00227022630391094"
        ixy="-2.54431260104897E-06"
        ixz="-6.64622684424124E-06"
        iyy="0.00267462162343889"
        iyz="-4.69650413333908E-08"
        izz="0.00123800916526073" />
    </inertial>
    <visual>
      <origin
        xyz="0 0 0"
        rpy="0 0 0" />
      <geometry>
        <mesh
          filename="package://huron_description_2/meshes/right_upper_thigh.STL" />
      </geometry>
      <material
        name="">
        <color
          rgba="1 1 1 1" />
      </material>
    </visual>
    <collision>
      <origin
        xyz="0 0 0"
        rpy="0 0 0" />
      <geometry>
        <mesh
          filename="package://huron_description_2/meshes/right_upper_thigh.STL" />
      </geometry>
    </collision>
  </link>
  <joint
    name="hip_2_right_upper_thigh"
    type="revolute">
    <origin
      xyz="0.0775000000000027 0 0"
      rpy="-3.14159265358979 0 0" />
    <parent
      link="base_link" />
    <child
      link="right_upper_thigh" />
    <axis
      xyz="0 0 1" />
    <limit
      lower="-3.14159"
      upper="3.14159"
      effort="0"
      velocity="0" />
  </joint>
  <link
    name="right_middle_thigh">
    <inertial>
      <origin
        xyz="0.0719500497192963 -0.00611520018078508 -0.00132607895244657"
        rpy="0 0 0" />
      <mass
        value="1.18837729131939" />
      <inertia
        ixx="0.000982215551324506"
        ixy="9.78567635679184E-08"
        ixz="-6.60736762566721E-07"
        iyy="0.000970452982433009"
        iyz="-9.85088275572797E-08"
        izz="0.000923660039693469" />
    </inertial>
    <visual>
      <origin
        xyz="0 0 0"
        rpy="0 0 0" />
      <geometry>
        <mesh
          filename="package://huron_description_2/meshes/right_middle_thigh.STL" />
      </geometry>
      <material
        name="">
        <color
          rgba="0.752941176470588 0.752941176470588 0.752941176470588 1" />
      </material>
    </visual>
    <collision>
      <origin
        xyz="0 0 0"
        rpy="0 0 0" />
      <geometry>
        <mesh
          filename="package://huron_description_2/meshes/right_middle_thigh.STL" />
      </geometry>
    </collision>
  </link>
  <joint
    name="right_thigh_roll"
    type="revolute">
    <origin
      xyz="0 0 0.1451242"
      rpy="1.5707963267949 0 0" />
    <parent
      link="right_upper_thigh" />
    <child
      link="right_middle_thigh" />
    <axis
      xyz="-0.0111238911817118 0 -0.999938127608392" />
    <limit
      lower="-3.14159"
      upper="3.14159"
      effort="0"
      velocity="0" />
  </joint>
  <link
    name="right_lower_thigh">
    <inertial>
      <origin
        xyz="-0.267528305398288 4.99568352568813E-05 0.0531316633422754"
        rpy="0 0 0" />
      <mass
        value="4.25435978482121" />
      <inertia
        ixx="0.00345009124368214"
        ixy="2.75609194373135E-09"
        ixz="-0.00197967910797871"
        iyy="0.0100350604541718"
        iyz="-2.52633173109223E-10"
        izz="0.0100902433938639" />
    </inertial>
    <visual>
      <origin
        xyz="0 0 0"
        rpy="0 0 0" />
      <geometry>
        <mesh
          filename="package://huron_description_2/meshes/right_lower_thigh.STL" />
      </geometry>
      <material
        name="">
        <color
          rgba="0.752941176470588 0.752941176470588 0.752941176470588 1" />
      </material>
    </visual>
    <collision>
      <origin
        xyz="0 0 0"
        rpy="0 0 0" />
      <geometry>
        <mesh
          filename="package://huron_description_2/meshes/right_lower_thigh.STL" />
        <!-- <cylinder length="0.5" radius="0.05" /> -->
      </geometry>
    </collision>
  </link>
  <joint
    name="right_thigh_pitch"
    type="revolute">
    <origin
      xyz="0 0 0"
      rpy="-1.58192044740287 0 -1.57079632679489" />
    <parent
      link="right_middle_thigh" />
    <child
      link="right_lower_thigh" />
    <axis
      xyz="0 0 -1" />
    <limit
      lower="-3.14159"
      upper="3.14159"
      effort="0"
      velocity="0" />
  </joint>
  <link
    name="right_shin">
    <inertial>
      <origin
        xyz="-0.114650881599689 -0.0200601310650421 -0.00081885215005037"
        rpy="0 0 0" />
      <mass
        value="1.60581203587773" />
      <inertia
        ixx="0.00116466025370797"
        ixy="-5.06243027863451E-06"
        ixz="-6.44736978767189E-10"
        iyy="0.00754378548249356"
        iyz="-2.59218140455744E-11"
        izz="0.0077351330344375" />
    </inertial>
    <visual>
      <origin
        xyz="0 0 0"
        rpy="0 0 0" />
      <geometry>
        <mesh
          filename="package://huron_description_2/meshes/right_shin.STL" />
      </geometry>
      <material
        name="">
        <color
          rgba="0.752941176470588 0.752941176470588 0.752941176470588 1" />
      </material>
    </visual>
    <collision>
      <origin
        xyz="0 0 0"
        rpy="0 0 0" />
      <!-- <origin -->
      <!--   xyz="-0.2125 -0.0115 0" -->
      <!--   rpy="0 1.57 0" /> -->
      <geometry>
        <mesh
          filename="package://huron_description_2/meshes/right_shin.STL" />
          <!-- <cylinder length="0.43" radius="0.05" /> -->
      </geometry>
    </collision>
  </link>
  <joint
    name="right_knee"
    type="revolute">
    <origin
      xyz="-0.512778478308813 4.99999999867273E-05 1.66647320091612E-05"
      rpy="0 0 0" />
    <parent
      link="right_lower_thigh" />
    <child
      link="right_shin" />
    <axis
      xyz="0 0 -1" />
    <limit
      lower="-3.14159"
      upper="3.14159"
      effort="0"
      velocity="0" />
  </joint>
  <link
    name="right_ankle_roll_link">
    <inertial>
      <origin
        xyz="-1.23603651862592E-05 5.57268410639189E-07 0.000277899308168073"
        rpy="0 0 0" />
      <mass
        value="0.0816413455622017" />
      <inertia
        ixx="2.09931500829249E-05"
        ixy="-5.12265171426306E-07"
        ixz="-2.80748290390765E-10"
        iyy="1.03508115313432E-05"
        iyz="4.07293289958981E-12"
        izz="2.23948011263121E-05" />
    </inertial>
    <visual>
      <origin
        xyz="0 0 0"
        rpy="0 0 0" />
      <geometry>
        <mesh
          filename="package://huron_description_2/meshes/right_ankle_roll_link.STL" />
      </geometry>
      <material
        name="">
        <color
          rgba="0.898039215686275 0.917647058823529 0.929411764705882 1" />
      </material>
    </visual>
    <collision>
      <origin
        xyz="0 0 0"
        rpy="0 0 0" />
      <geometry>
        <mesh
          filename="package://huron_description_2/meshes/right_ankle_roll_link.STL" />
      </geometry>
    </collision>
  </link>
  <joint
    name="right_ankle_roll"
    type="revolute">
    <origin
      xyz="-0.425000000000006 -0.0344999999999848 0"
      rpy="1.5707963267949 0 0" />
    <parent
      link="right_shin" />
    <child
      link="right_ankle_roll_link" />
    <axis
      xyz="0 0 1" />
    <limit
      lower="-3.14159"
      upper="3.14159"
      effort="0"
      velocity="0" />
  </joint>
  <link
    name="right_foot">
    <inertial>
      <origin
        xyz="-0.027041 -0.034311 0.00083258"
        rpy="0 0 0" />
      <mass
        value="2.6907" />
      <inertia
        ixx="0.0080929"
        ixy="0.00024558"
        ixz="-5.8611E-05"
        iyy="0.0012877"
        iyz="0.0001125"
        izz="0.0070808" />
    </inertial>
    <visual>
      <origin
        xyz="0 0 0"
        rpy="0 0 0" />
      <geometry>
        <mesh
          filename="package://huron_description_2/meshes/right_foot.STL" />
      </geometry>
      <material
        name="">
        <color
          rgba="0.89804 0.91765 0.92941 1" />
      </material>
    </visual>
    <collision>
      <origin
        xyz="0 0 0"
        rpy="0 0 0" />
      <geometry>
        <mesh
          filename="package://huron_description_2/meshes/right_foot.STL" />
      </geometry>
    </collision>
  </link>
  <joint
    name="right_ankle_pitch"
    type="revolute">
    <origin
      xyz="0 0 0"
      rpy="-1.5707963267949 0 0" />
    <parent
      link="right_ankle_roll_link" />
    <child
      link="right_foot" />
    <axis
      xyz="-0.04796849471608 0 -0.998848849183235" />
    <limit
      lower="-3.14159"
      upper="3.14159"
      effort="0"
      velocity="0" />
  </joint>
</robot>
