<?xml version="1.0" encoding="utf-8"?>
<!-- This URDF was automatically created by SolidWorks to URDF Exporter! Originally created by Stephen Brawner (brawner@gmail.com) 
     Commit Version: 1.6.0-4-g7f85cfe  Build Version: 1.6.7995.38578
     For more information, please see http://wiki.ros.org/sw_urdf_exporter -->
<robot
  name="huron_description_3">

  <gazebo>
    <self_collide>1</self_collide>
  </gazebo>

  <link name="base_footprint" />
  <link
    name="base_link">
    <inertial>
      <origin
        xyz="4.7319E-09 5.4338E-07 0.026975"
        rpy="0 0 0" />
      <mass
        value="3.4072" />
      <inertia
        ixx="0.00319"
        ixy="7.149E-11"
        ixz="6.0313E-11"
        iyy="0.010531"
        iyz="6.926E-09"
        izz="0.012315" />
    </inertial>
    <visual>
      <origin
        xyz="0 0 0"
        rpy="0 0 0" />
      <geometry>
        <mesh
          filename="package://huron_description_3/meshes/base_link.STL" />
      </geometry>
      <material
        name="">
        <color
          rgba="0.75294 0.75294 0.75294 1" />
      </material>
    </visual>
    <collision>
      <origin
        xyz="0 0 0"
        rpy="0 0 0" />
      <geometry>
        <mesh
          filename="package://huron_description_3/meshes/base_link.STL" />
      </geometry>
    </collision>
  </link>
  <joint name="base_joint" type="fixed">
    <parent link="base_footprint"/>
    <child link="base_link"/>
    <!-- <origin xyz="0.0 0.0 0.0" rpy="0 0 0"/> -->
    <origin xyz="0.0 0.0 1.3" rpy="0 0 0"/>
  </joint>
  <link
    name="left_upper_thigh">
    <inertial>
      <origin
        xyz="0.00063027 0.00053867 0.081628"
        rpy="0 0 0" />
      <mass
        value="1.6968" />
      <inertia
        ixx="0.0022702"
        ixy="-2.5443E-06"
        ixz="-6.6462E-06"
        iyy="0.0026746"
        iyz="-4.6965E-08"
        izz="0.001238" />
    </inertial>
    <visual>
      <origin
        xyz="0 0 0"
        rpy="0 0 0" />
      <geometry>
        <mesh
          filename="package://huron_description_3/meshes/left_upper_thigh.STL" />
      </geometry>
      <material
        name="">
        <color
          rgba="0.75294 0.75294 0.75294 1" />
      </material>
    </visual>
    <collision>
      <origin
        xyz="0 0 0"
        rpy="0 0 0" />
      <geometry>
        <mesh
          filename="package://huron_description_3/meshes/left_upper_thigh.STL" />
      </geometry>
    </collision>
  </link>
  <joint
    name="hip_2_left_upper_thigh"
    type="revolute">
    <origin
      xyz="-0.0775 0 0"
      rpy="3.1416 0 0" />
    <parent
      link="base_link" />
    <child
      link="left_upper_thigh" />
    <axis
      xyz="0 0 1" />
    <limit
      lower="-3.14159"
      upper="3.14159"
      effort="0"
      velocity="0" />
  </joint>
  <link
    name="left_middle_thigh">
    <inertial>
      <origin
        xyz="-0.071962 -0.0061153 -6.8323E-05"
        rpy="0 0 0" />
      <mass
        value="1.1884" />
      <inertia
        ixx="0.00098222"
        ixy="-9.8651E-08"
        ixz="-3.7349E-07"
        iyy="0.00097045"
        iyz="9.7904E-08"
        izz="0.00092365" />
    </inertial>
    <visual>
      <origin
        xyz="0 0 0"
        rpy="0 0 0" />
      <geometry>
        <mesh
          filename="package://huron_description_3/meshes/left_middle_thigh.STL" />
      </geometry>
      <material
        name="">
        <color
          rgba="0.75294 0.75294 0.75294 1" />
      </material>
    </visual>
    <collision>
      <origin
        xyz="0 0 0"
        rpy="0 0 0" />
      <geometry>
        <mesh
          filename="package://huron_description_3/meshes/left_middle_thigh.STL" />
      </geometry>
    </collision>
  </link>
  <joint
    name="left_thigh_roll"
    type="revolute">
    <origin
      xyz="0 0 0.14512"
      rpy="1.5708 0 0" />
    <parent
      link="left_upper_thigh" />
    <child
      link="left_middle_thigh" />
    <axis
      xyz="-0.0062919 0 -0.99998" />
    <limit
      lower="-3.14159"
      upper="3.14159"
      effort="0"
      velocity="0" />
  </joint>
  <link
    name="left_lower_thigh">
    <inertial>
      <origin
        xyz="-0.26603 -0.00028821 -0.053151"
        rpy="0 0 0" />
      <mass
        value="4.2544" />
      <inertia
        ixx="0.0034527"
        ixy="1.2487E-05"
        ixz="0.0019796"
        iyy="0.010032"
        iyz="3.6402E-07"
        izz="0.01009" />
    </inertial>
    <visual>
      <origin
        xyz="0 0 0"
        rpy="0 0 0" />
      <geometry>
        <mesh
          filename="package://huron_description_3/meshes/left_lower_thigh.STL" />
      </geometry>
      <material
        name="">
        <color
          rgba="0.75294 0.75294 0.75294 1" />
      </material>
    </visual>
    <collision>
      <origin
        xyz="0 0 0"
        rpy="0 0 0" />
      <geometry>
        <mesh
          filename="package://huron_description_3/meshes/left_lower_thigh.STL" />
      </geometry>
    </collision>
  </link>
  <joint
    name="left_thigh_pitch"
    type="revolute">
    <origin
      xyz="0 0 0"
      rpy="-1.5708 0 -1.5708" />
    <parent
      link="left_middle_thigh" />
    <child
      link="left_lower_thigh" />
    <axis
      xyz="0 0.0062919 0.99998" />
    <limit
      lower="-3.14159"
      upper="3.14159"
      effort="0"
      velocity="0" />
  </joint>
  <link
    name="left_shin">
    <inertial>
      <origin
        xyz="-0.11465 -0.02006 0.00081884"
        rpy="0 0 0" />
      <mass
        value="1.6058" />
      <inertia
        ixx="0.0011647"
        ixy="-5.0624E-06"
        ixz="-2.9504E-10"
        iyy="0.0075438"
        iyz="-2.6087E-11"
        izz="0.0077351" />
    </inertial>
    <visual>
      <origin
        xyz="0 0 0"
        rpy="0 0 0" />
      <geometry>
        <mesh
          filename="package://huron_description_3/meshes/left_shin.STL" />
      </geometry>
      <material
        name="">
        <color
          rgba="0.75294 0.75294 0.75294 1" />
      </material>
    </visual>
    <collision>
      <origin
        xyz="0 0 0"
        rpy="0 0 0" />
      <geometry>
        <mesh
          filename="package://huron_description_3/meshes/left_shin.STL" />
      </geometry>
    </collision>
  </link>
  <joint
    name="left_knee"
    type="revolute">
    <origin
      xyz="-0.51128 4.9894E-05 -1.6979E-05"
      rpy="-0.0062919 0 0" />
    <parent
      link="left_lower_thigh" />
    <child
      link="left_shin" />
    <axis
      xyz="0 0 1" />
    <limit
      lower="-3.14159"
      upper="3.14159"
      effort="0"
      velocity="0" />
  </joint>
  <link
    name="left_ankle_roll_link">
    <inertial>
      <origin
        xyz="-1.236E-05 5.5727E-07 0.0002779"
        rpy="0 0 0" />
      <mass
        value="0.081641" />
      <inertia
        ixx="2.0993E-05"
        ixy="-5.1227E-07"
        ixz="-2.8075E-10"
        iyy="1.0351E-05"
        iyz="4.0729E-12"
        izz="2.2395E-05" />
    </inertial>
    <visual>
      <origin
        xyz="0 0 0"
        rpy="0 0 0" />
      <geometry>
        <mesh
          filename="package://huron_description_3/meshes/left_ankle_roll_link.STL" />
      </geometry>
      <material
        name="">
        <color
          rgba="0.89804 0.91765 0.92941 1" />
      </material>
    </visual>
    <collision>
      <origin
        xyz="0 0 0"
        rpy="0 0 0" />
      <geometry>
        <mesh
          filename="package://huron_description_3/meshes/left_ankle_roll_link.STL" />
      </geometry>
    </collision>
  </link>
  <joint
    name="left_ankle_roll"
    type="revolute">
    <origin
      xyz="-0.425 -0.0345 0"
      rpy="1.5708 0 0" />
    <parent
      link="left_shin" />
    <child
      link="left_ankle_roll_link" />
    <axis
      xyz="0 0 1" />
    <limit
      lower="-3.14159"
      upper="3.14159"
      effort="0"
      velocity="0" />
  </joint>
  <link
    name="left_foot">
    <inertial>
      <origin
        xyz="-0.027041 -0.034311 0.00083257"
        rpy="0 0 0" />
      <mass
        value="2.6907" />
      <inertia
        ixx="0.0080929"
        ixy="0.00024558"
        ixz="-5.8611E-05"
        iyy="0.0012877"
        iyz="0.0001125"
        izz="0.0070808" />
    </inertial>
    <visual>
      <origin
        xyz="0 0 0"
        rpy="0 0 0" />
      <geometry>
        <mesh
          filename="package://huron_description_3/meshes/left_foot.STL" />
      </geometry>
      <material
        name="">
        <color
          rgba="0.89804 0.91765 0.92941 1" />
      </material>
    </visual>
    <collision>
      <origin
        xyz="0 0 0"
        rpy="0 0 0" />
      <geometry>
        <mesh
          filename="package://huron_description_3/meshes/left_foot.STL" />
      </geometry>
    </collision>
  </link>
  <joint
    name="left_ankle_pitch"
    type="revolute">
    <origin
      xyz="0 0 0"
      rpy="-1.5708 0 0" />
    <parent
      link="left_ankle_roll_link" />
    <child
      link="left_foot" />
    <axis
      xyz="-0.047968 0 -0.99885" />
    <limit
      lower="-3.14159"
      upper="3.14159"
      effort="0"
      velocity="0" />
  </joint>
  <link
    name="right_upper_thigh">
    <inertial>
      <origin
        xyz="-0.00063014 0.00051325 0.081619"
        rpy="0 0 0" />
      <mass
        value="1.6968" />
      <inertia
        ixx="0.0022729"
        ixy="-4.4685E-06"
        ixz="6.646E-06"
        iyy="0.0026746"
        iyz="6.8245E-08"
        izz="0.0012354" />
    </inertial>
    <visual>
      <origin
        xyz="0 0 0"
        rpy="0 0 0" />
      <geometry>
        <mesh
          filename="package://huron_description_3/meshes/right_upper_thigh.STL" />
      </geometry>
      <material
        name="">
        <color
          rgba="0.75294 0.75294 0.75294 1" />
      </material>
    </visual>
    <collision>
      <origin
        xyz="0 0 0"
        rpy="0 0 0" />
      <geometry>
        <mesh
          filename="package://huron_description_3/meshes/right_upper_thigh.STL" />
      </geometry>
    </collision>
  </link>
  <joint
    name="hip_2_right_upper_thigh"
    type="revolute">
    <origin
      xyz="0.0775 0 0"
      rpy="-3.1416 0 0" />
    <parent
      link="base_link" />
    <child
      link="right_upper_thigh" />
    <axis
      xyz="0 0 1" />
    <limit
      lower="-3.1416"
      upper="3.1416"
      effort="0"
      velocity="0" />
  </joint>
  <link
    name="right_middle_thigh">
    <inertial>
      <origin
        xyz="0.07195 -0.0061152 -0.0013261"
        rpy="0 0 0" />
      <mass
        value="1.1884" />
      <inertia
        ixx="0.00098222"
        ixy="9.7857E-08"
        ixz="-6.6074E-07"
        iyy="0.00097045"
        iyz="-9.8509E-08"
        izz="0.00092366" />
    </inertial>
    <visual>
      <origin
        xyz="0 0 0"
        rpy="0 0 0" />
      <geometry>
        <mesh
          filename="package://huron_description_3/meshes/right_middle_thigh.STL" />
      </geometry>
      <material
        name="">
        <color
          rgba="0.75294 0.75294 0.75294 1" />
      </material>
    </visual>
    <collision>
      <origin
        xyz="0 0 0"
        rpy="0 0 0" />
      <geometry>
        <mesh
          filename="package://huron_description_3/meshes/right_middle_thigh.STL" />
      </geometry>
    </collision>
  </link>
  <joint
    name="right_thigh_roll"
    type="revolute">
    <origin
      xyz="0 0 0.14512"
      rpy="1.5708 0 0" />
    <parent
      link="right_upper_thigh" />
    <child
      link="right_middle_thigh" />
    <axis
      xyz="-0.011124 0 -0.99994" />
    <limit
      lower="-3.1416"
      upper="3.1416"
      effort="0"
      velocity="0" />
  </joint>
  <link
    name="right_lower_thigh">
    <inertial>
      <origin
        xyz="-0.26753 4.9957E-05 0.053132"
        rpy="0 0 0" />
      <mass
        value="4.2544" />
      <inertia
        ixx="0.0034501"
        ixy="2.7561E-09"
        ixz="-0.0019797"
        iyy="0.010035"
        iyz="-2.5263E-10"
        izz="0.01009" />
    </inertial>
    <visual>
      <origin
        xyz="0 0 0"
        rpy="0 0 0" />
      <geometry>
        <mesh
          filename="package://huron_description_3/meshes/right_lower_thigh.STL" />
      </geometry>
      <material
        name="">
        <color
          rgba="0.75294 0.75294 0.75294 1" />
      </material>
    </visual>
    <collision>
      <origin
        xyz="0 0 0"
        rpy="0 0 0" />
      <geometry>
        <mesh
          filename="package://huron_description_3/meshes/right_lower_thigh.STL" />
      </geometry>
    </collision>
  </link>
  <joint
    name="right_thigh_pitch"
    type="revolute">
    <origin
      xyz="0 0 0"
      rpy="-1.5819 0 -1.5708" />
    <parent
      link="right_middle_thigh" />
    <child
      link="right_lower_thigh" />
    <axis
      xyz="0 0 -1" />
    <limit
      lower="-3.14159"
      upper="3.14159"
      effort="0"
      velocity="0" />
  </joint>
  <link
    name="right_shin">
    <inertial>
      <origin
        xyz="-0.11465 -0.02006 -0.00081885"
        rpy="0 0 0" />
      <mass
        value="1.6058" />
      <inertia
        ixx="0.0011647"
        ixy="-5.0624E-06"
        ixz="-6.4474E-10"
        iyy="0.0075438"
        iyz="-2.5922E-11"
        izz="0.0077351" />
    </inertial>
    <visual>
      <origin
        xyz="0 0 0"
        rpy="0 0 0" />
      <geometry>
        <mesh
          filename="package://huron_description_3/meshes/right_shin.STL" />
      </geometry>
      <material
        name="">
        <color
          rgba="0.75294 0.75294 0.75294 1" />
      </material>
    </visual>
    <collision>
      <origin
        xyz="0 0 0"
        rpy="0 0 0" />
      <geometry>
        <mesh
          filename="package://huron_description_3/meshes/right_shin.STL" />
      </geometry>
    </collision>
  </link>
  <joint
    name="right_knee"
    type="revolute">
    <origin
      xyz="-0.51278 5E-05 1.6665E-05"
      rpy="0 0 0" />
    <parent
      link="right_lower_thigh" />
    <child
      link="right_shin" />
    <axis
      xyz="0 0 -1" />
    <limit
      lower="-3.14159"
      upper="3.14159"
      effort="0"
      velocity="0" />
  </joint>
  <link
    name="right_ankle_roll_link">
    <inertial>
      <origin
        xyz="-1.236E-05 5.5727E-07 0.0002779"
        rpy="0 0 0" />
      <mass
        value="0.081641" />
      <inertia
        ixx="2.0993E-05"
        ixy="-5.1227E-07"
        ixz="-2.8075E-10"
        iyy="1.0351E-05"
        iyz="4.0729E-12"
        izz="2.2395E-05" />
    </inertial>
    <visual>
      <origin
        xyz="0 0 0"
        rpy="0 0 0" />
      <geometry>
        <mesh
          filename="package://huron_description_3/meshes/right_ankle_roll_link.STL" />
      </geometry>
      <material
        name="">
        <color
          rgba="0.89804 0.91765 0.92941 1" />
      </material>
    </visual>
    <collision>
      <origin
        xyz="0 0 0"
        rpy="0 0 0" />
      <geometry>
        <mesh
          filename="package://huron_description_3/meshes/right_ankle_roll_link.STL" />
      </geometry>
    </collision>
  </link>
  <joint
    name="right_ankle_roll"
    type="revolute">
    <origin
      xyz="-0.425 -0.0345 0"
      rpy="1.5708 0 0" />
    <parent
      link="right_shin" />
    <child
      link="right_ankle_roll_link" />
    <axis
      xyz="0 0 1" />
    <limit
      lower="-3.14159"
      upper="3.14159"
      effort="0"
      velocity="0" />
  </joint>
  <link
    name="right_foot">
    <inertial>
      <origin
        xyz="-0.027041 -0.034311 0.00083258"
        rpy="0 0 0" />
      <mass
        value="2.6907" />
      <inertia
        ixx="0.0080929"
        ixy="0.00024558"
        ixz="-5.8611E-05"
        iyy="0.0012877"
        iyz="0.0001125"
        izz="0.0070808" />
    </inertial>
    <visual>
      <origin
        xyz="0 0 0"
        rpy="0 0 0" />
      <geometry>
        <mesh
          filename="package://huron_description_3/meshes/right_foot.STL" />
      </geometry>
      <material
        name="">
        <color
          rgba="0.89804 0.91765 0.92941 1" />
      </material>
    </visual>
    <collision>
      <origin
        xyz="0 0 0"
        rpy="0 0 0" />
      <geometry>
        <mesh
          filename="package://huron_description_3/meshes/right_foot.STL" />
      </geometry>
    </collision>
  </link>
  <joint
    name="right_ankle_pitch"
    type="revolute">
    <origin
      xyz="0 0 0"
      rpy="-1.5708 0 0" />
    <parent
      link="right_ankle_roll_link" />
    <child
      link="right_foot" />
    <axis
      xyz="-0.047968 0 -0.99885" />
    <limit
      lower="-3.14159"
      upper="3.14159"
      effort="0"
      velocity="0" />
  </joint>
</robot>
