<?xml version="1.0" ?>
<!-- =================================================================================== -->
<!-- |    This document was autogenerated by xacro from huron.xacro                    | -->
<!-- |    EDITING THIS FILE BY HAND IS NOT RECOMMENDED                                 | -->
<!-- =================================================================================== -->
<robot name="huron">
  <material name="black">
    <color rgba="0.0 0.0 0.0 1.0"/>
  </material>
  <material name="blue">
    <color rgba="0.0 0.0 0.8 1.0"/>
  </material>
  <material name="green">
    <color rgba="0.0 0.8 0.0 1.0"/>
  </material>
  <material name="grey">
    <color rgba="0.75294 0.75294 0.75294 1"/>
  </material>
  <material name="orange">
    <color rgba="1.0 0.4235294117647059 0.0392156862745098 1.0"/>
  </material>
  <material name="brown">
    <color rgba="0.8705882352941177 0.8117647058823529 0.7647058823529411 1.0"/>
  </material>
  <material name="red">
    <color rgba="0.8 0.0 0.0 1.0"/>
  </material>
  <material name="white">
    <color rgba="1.0 1.0 1.0 1.0"/>
  </material>
  <!-- Right leg -->
  <!-- Right foot sensors -->
  <!-- ros_control plugin -->
  <gazebo>
    <plugin filename="libgazebo_ros_control.so" name="gazebo_ros_control">
      <robotNamespace>/huron</robotNamespace>
    </plugin>
  </gazebo>
  <gazebo>
    <plugin filename="libgazebo_ros_p3d.so" name="ground_truth">
      <frameName>map</frameName>
      <bodyName>base_link</bodyName>
      <topicName>/huron/odom</topicName>
      <updateRate>100.0</updateRate>
    </plugin>
  </gazebo>
  <!-- imu sensor -->
  <gazebo reference="imu_link">
    <gravity>true</gravity>
    <sensor name="imu_sensor" type="imu">
      <always_on>true</always_on>
      <update_rate>100</update_rate>
      <visualize>true</visualize>
      <topic>/huron/sensor/imu</topic>
      <plugin filename="libgazebo_ros_imu_sensor.so" name="imu_plugin">
        <topicName>huron/sensor/imu</topicName>
        <bodyName>imu_link</bodyName>
        <updateRateHZ>10.0</updateRateHZ>
        <gaussianNoise>0.0</gaussianNoise>
        <xyzOffset>0 0 0</xyzOffset>
        <rpyOffset>0 0 0</rpyOffset>
        <frameName>imu_link</frameName>
      </plugin>
      <pose>0 0 0 0 0 0</pose>
    </sensor>
  </gazebo>
  <gazebo reference="r1_ft_fixed">
    <provideFeedback>true</provideFeedback>
  </gazebo>
  <gazebo>
    <plugin filename="libgazebo_ros_ft_sensor.so" name="r1_ft_sensor">
      <updateRate>100.0</updateRate>
      <topicName>/huron/sensor/r1_ft_sensor</topicName>
      <jointName>r1_ft_fixed</jointName>
      <gaussianNoise>0.0</gaussianNoise>
    </plugin>
  </gazebo>
  <gazebo reference="r2_ft_fixed">
    <provideFeedback>true</provideFeedback>
  </gazebo>
  <gazebo>
    <plugin filename="libgazebo_ros_ft_sensor.so" name="r2_ft_sensor">
      <updateRate>100.0</updateRate>
      <topicName>/huron/sensor/r2_ft_sensor</topicName>
      <jointName>r2_ft_fixed</jointName>
      <gaussianNoise>0.0</gaussianNoise>
    </plugin>
  </gazebo>
  <gazebo reference="r3_ft_fixed">
    <provideFeedback>true</provideFeedback>
  </gazebo>
  <gazebo>
    <plugin filename="libgazebo_ros_ft_sensor.so" name="r3_ft_sensor">
      <updateRate>100.0</updateRate>
      <topicName>/huron/sensor/r3_ft_sensor</topicName>
      <jointName>r3_ft_fixed</jointName>
      <gaussianNoise>0.0</gaussianNoise>
    </plugin>
  </gazebo>
  <gazebo reference="r4_ft_fixed">
    <provideFeedback>true</provideFeedback>
  </gazebo>
  <gazebo>
    <plugin filename="libgazebo_ros_ft_sensor.so" name="r4_ft_sensor">
      <updateRate>100.0</updateRate>
      <topicName>/huron/sensor/r4_ft_sensor</topicName>
      <jointName>r4_ft_fixed</jointName>
      <gaussianNoise>0.0</gaussianNoise>
    </plugin>
  </gazebo>
  <gazebo reference="l1_ft_fixed">
    <provideFeedback>true</provideFeedback>
  </gazebo>
  <gazebo>
    <plugin filename="libgazebo_ros_ft_sensor.so" name="l1_ft_sensor">
      <updateRate>100.0</updateRate>
      <topicName>/huron/sensor/l1_ft_sensor</topicName>
      <jointName>l1_ft_fixed</jointName>
      <gaussianNoise>0.0</gaussianNoise>
    </plugin>
  </gazebo>
  <gazebo reference="l2_ft_fixed">
    <provideFeedback>true</provideFeedback>
  </gazebo>
  <gazebo>
    <plugin filename="libgazebo_ros_ft_sensor.so" name="l2_ft_sensor">
      <updateRate>100.0</updateRate>
      <topicName>/huron/sensor/l2_ft_sensor</topicName>
      <jointName>l2_ft_fixed</jointName>
      <gaussianNoise>0.0</gaussianNoise>
    </plugin>
  </gazebo>
  <gazebo reference="l3_ft_fixed">
    <provideFeedback>true</provideFeedback>
  </gazebo>
  <gazebo>
    <plugin filename="libgazebo_ros_ft_sensor.so" name="l3_ft_sensor">
      <updateRate>100.0</updateRate>
      <topicName>/huron/sensor/l3_ft_sensor</topicName>
      <jointName>l3_ft_fixed</jointName>
      <gaussianNoise>0.0</gaussianNoise>
    </plugin>
  </gazebo>
  <gazebo reference="l4_ft_fixed">
    <provideFeedback>true</provideFeedback>
  </gazebo>
  <gazebo>
    <plugin filename="libgazebo_ros_ft_sensor.so" name="r4_ft_sensor">
      <updateRate>100.0</updateRate>
      <topicName>/huron/sensor/l4_ft_sensor</topicName>
      <jointName>l4_ft_fixed</jointName>
      <gaussianNoise>0.0</gaussianNoise>
    </plugin>
  </gazebo>
  <!-- World -->
  <gazebo reference="world"/>
  <!-- Map -->
  <gazebo reference="map"/>
  <!-- Base -->
  <gazebo reference="base_link"/>
  <!-- IMU -->
  <gazebo reference="imu_link"/>
  <!-- Body-->
  <gazebo reference="base_footprint">
    <mu1>0.2</mu1>
    <mu2>0.2</mu2>
    <material>Gazebo/Grey</material>
    <selfCollide>true</selfCollide>
  </gazebo>
  <!-- Left Leg -->
  <gazebo reference="l_hip_yaw_link">
    <mu1>0.2</mu1>
    <mu2>0.2</mu2>
    <material>Gazebo/Grey</material>
    <selfCollide>true</selfCollide>
  </gazebo>
  <gazebo reference="l_hip_roll_link">
    <mu1>0.2</mu1>
    <mu2>0.2</mu2>
    <material>Gazebo/Grey</material>
    <selfCollide>true</selfCollide>
  </gazebo>
  <gazebo reference="l_hip_pitch_link">
    <mu1>0.2</mu1>
    <mu2>0.2</mu2>
    <material>Gazebo/Grey</material>
    <selfCollide>true</selfCollide>
  </gazebo>
  <gazebo reference="l_knee_pitch_link">
    <mu1>0.2</mu1>
    <mu2>0.2</mu2>
    <material>Gazebo/Grey</material>
    <selfCollide>true</selfCollide>
  </gazebo>
  <gazebo reference="l_ankle_pitch_link">
    <mu1>0.2</mu1>
    <mu2>0.2</mu2>
    <material>Gazebo/Grey</material>
    <selfCollide>true</selfCollide>
  </gazebo>
  <gazebo reference="l_ankle_roll_link">
    <kp>100000.0</kp>
    <kd>100.0</kd>
    <mu1>0.9</mu1>
    <mu2>0.9</mu2>
    <!--<maxContacts>30</maxContacts>-->
    <fdir1>1 1 0</fdir1>
    <maxVel>1.0</maxVel>
    <minDepth>0.001</minDepth>
    <material>Gazebo/Blue</material>
  </gazebo>
  <gazebo reference="l1_foot_ft_link">
    <kp>100000.0</kp>
    <kd>100.0</kd>
    <mu1>0.9</mu1>
    <mu2>0.9</mu2>
    <!--<maxContacts>30</maxContacts>-->
    <fdir1>1 1 0</fdir1>
    <maxVel>1.0</maxVel>
    <minDepth>0.0001</minDepth>
    <material>Gazebo/Black</material>
  </gazebo>
  <gazebo reference="l2_foot_ft_link">
    <kp>100000.0</kp>
    <kd>100.0</kd>
    <mu1>0.9</mu1>
    <mu2>0.9</mu2>
    <!--<maxContacts>30</maxContacts>-->
    <fdir1>1 1 0</fdir1>
    <maxVel>1.0</maxVel>
    <minDepth>0.0001</minDepth>
    <material>Gazebo/Black</material>
  </gazebo>
  <gazebo reference="l3_foot_ft_link">
    <kp>100000.0</kp>
    <kd>100.0</kd>
    <mu1>0.9</mu1>
    <mu2>0.9</mu2>
    <!--<maxContacts>30</maxContacts>-->
    <fdir1>1 1 0</fdir1>
    <maxVel>1.0</maxVel>
    <minDepth>0.0001</minDepth>
    <material>Gazebo/Black</material>
  </gazebo>
  <gazebo reference="l4_foot_ft_link">
    <kp>100000.0</kp>
    <kd>100.0</kd>
    <mu1>0.9</mu1>
    <mu2>0.9</mu2>
    <!--<maxContacts>30</maxContacts>-->
    <fdir1>1 1 0</fdir1>
    <maxVel>1.0</maxVel>
    <minDepth>0.0001</minDepth>
    <material>Gazebo/Black</material>
  </gazebo>
  <!-- Right Leg -->
  <gazebo reference="r_hip_yaw_link">
    <mu1>0.2</mu1>
    <mu2>0.2</mu2>
    <material>Gazebo/Grey</material>
    <selfCollide>true</selfCollide>
  </gazebo>
  <gazebo reference="r_hip_roll_link">
    <mu1>0.2</mu1>
    <mu2>0.2</mu2>
    <material>Gazebo/Grey</material>
    <selfCollide>true</selfCollide>
  </gazebo>
  <gazebo reference="r_hip_pitch_link">
    <mu1>0.2</mu1>
    <mu2>0.2</mu2>
    <material>Gazebo/Grey</material>
    <selfCollide>true</selfCollide>
  </gazebo>
  <gazebo reference="r_knee_pitch_link">
    <mu1>0.2</mu1>
    <mu2>0.2</mu2>
    <material>Gazebo/Grey</material>
    <selfCollide>true</selfCollide>
  </gazebo>
  <gazebo reference="r_ankle_pitch_link">
    <mu1>0.2</mu1>
    <mu2>0.2</mu2>
    <material>Gazebo/Grey</material>
    <selfCollide>true</selfCollide>
  </gazebo>
  <gazebo reference="r_ankle_roll_link">
    <kp>100000.0</kp>
    <kd>100.0</kd>
    <mu1>0.9</mu1>
    <mu2>0.9</mu2>
    <!--<maxContacts>30</maxContacts>-->
    <fdir1>1 1 0</fdir1>
    <maxVel>1.0</maxVel>
    <minDepth>0.0001</minDepth>
    <material>Gazebo/Blue</material>
  </gazebo>
  <gazebo reference="r1_foot_ft_link">
    <kp>100000.0</kp>
    <kd>100.0</kd>
    <mu1>0.9</mu1>
    <mu2>0.9</mu2>
    <!--<maxContacts>30</maxContacts>-->
    <fdir1>1 1 0</fdir1>
    <maxVel>1.0</maxVel>
    <minDepth>0.0001</minDepth>
    <material>Gazebo/Black</material>
  </gazebo>
  <gazebo reference="r2_foot_ft_link">
    <kp>100000.0</kp>
    <kd>100.0</kd>
    <mu1>0.9</mu1>
    <mu2>0.9</mu2>
    <!--<maxContacts>30</maxContacts>-->
    <fdir1>1 1 0</fdir1>
    <maxVel>1.0</maxVel>
    <minDepth>0.0001</minDepth>
    <material>Gazebo/Black</material>
  </gazebo>
  <gazebo reference="r3_foot_ft_link">
    <kp>100000.0</kp>
    <kd>100.0</kd>
    <mu1>0.9</mu1>
    <mu2>0.9</mu2>
    <!--<maxContacts>30</maxContacts>-->
    <fdir1>1 1 0</fdir1>
    <maxVel>1.0</maxVel>
    <minDepth>0.0001</minDepth>
    <material>Gazebo/Black</material>
  </gazebo>
  <gazebo reference="r4_foot_ft_link">
    <kp>100000.0</kp>
    <kd>100.0</kd>
    <mu1>0.9</mu1>
    <mu2>0.9</mu2>
    <!--<maxContacts>30</maxContacts>-->
    <fdir1>1 1 0</fdir1>
    <maxVel>1.0</maxVel>
    <minDepth>0.0001</minDepth>
    <material>Gazebo/Black</material>
  </gazebo>
  <!-- Used for fixing robot -->
  <!--<link name="world"></link> 
    <joint name="world_fixed" type="fixed">
        <origin xyz="0 0 0.764" rpy="0 0 0"/>
        <parent link="world"/>
        <child link="base_link"/>
    </joint> -->
  <link name="base_link"/>
  <joint name="base_fixed" type="fixed">
    <origin rpy="0 0 0" xyz="0 0 0"/>
    <parent link="base_link"/>
    <child link="base_footprint"/>
  </joint>
  <!-- base_link -->
  <link name="base_footprint">
    <visual>
      <origin rpy="0 0 0" xyz="0 0 0"/>
      <geometry>
        <mesh filename="package://huron_description/meshes/base_link.STL" scale="1 1 1"/>
      </geometry>
      <material name="grey"/>
    </visual>
    <collision>
      <origin rpy="0 0 0" xyz="0 0 0"/>
      <geometry>
        <mesh filename="package://huron_description/meshes/base_link.STL" scale="1 1 1"/>
      </geometry>
      <material name="grey"/>
    </collision>
    <inertial>
      <origin rpy="0 0 0" xyz="4.7319E-09 5.4338E-07 0.026975"/>
      <mass value="3.4072"/>
      <inertia ixx="0.00319" ixy="7.149E-11" ixz="6.0313E-11" iyy="0.010531" iyz="6.926E-09" izz="0.012315"/>
    </inertial>
  </link>
  <!-- imu joint -->
  <joint name="imu_fixed" type="fixed">
    <origin rpy="0 0 0" xyz="0 0 0"/>
    <parent link="base_footprint"/>
    <child link="imu_link"/>
  </joint>
  <link name="imu_link"/>
  <!-- right hip yaw joint -->
  <joint name="r_hip_yaw_joint" type="revolute">
    <origin rpy="0 0 3.13046853298182" xyz="0.0774999999999944 0 -0.1451242"/>
    <parent link="base_footprint"/>
    <child link="r_hip_yaw_link"/>
    <axis xyz="0 0 1"/>
    <limit effort="1000" lower="-3.1416" upper="3.1416" velocity="3"/>
    <dynamics damping="0.5" friction="100"/>
  </joint>
  <transmission name="r_hip_yaw_joint_tran">
    <type>transmission_interface/SimpleTransmission</type>
    <joint name="r_hip_yaw_joint">
      <hardwareInterface>hardware_interface/EffortJointInterface</hardwareInterface>
    </joint>
    <actuator name="r_hip_yaw_joint_motor">
      <hardwareInterface>EffortJointInterface</hardwareInterface>
      <mechanicalReduction>1</mechanicalReduction>
    </actuator>
  </transmission>
  <!-- right hip yaw link -->
  <link name="r_hip_yaw_link">
    <visual>
      <origin rpy="0 0 0" xyz="0 0 0"/>
      <geometry>
        <mesh filename="package://huron_description/meshes/r_hip_yaw_link.STL" scale="1 1 1"/>
      </geometry>
      <material name="grey"/>
    </visual>
    <collision>
      <origin rpy="0 0 0" xyz="0 0 0"/>
      <geometry>
        <mesh filename="package://huron_description/meshes/r_hip_yaw_link.STL" scale="1 1 1"/>
      </geometry>
      <material name="grey"/>
    </collision>
    <inertial>
      <origin rpy="0 0 0" xyz="0.0006244 0.00052023 0.063505"/>
      <mass value="1.6968"/>
      <inertia ixx="0.0022729" ixy="-5.6517E-10" ixz="6.6464E-06" iyy="0.0026746" iyz="5.6889E-09" izz="0.0012354"/>
    </inertial>
  </link>
  <!-- right hip roll joint-->
  <joint name="r_hip_roll_joint" type="revolute">
    <origin rpy="1.5708 0 0" xyz="0 0 0"/>
    <parent link="r_hip_yaw_link"/>
    <child link="r_hip_roll_link"/>
    <axis xyz="0 0 1"/>
    <limit effort="1000" lower="-3.1416" upper="3.1416" velocity="3"/>
    <dynamics damping="0.5" friction="100"/>
  </joint>
  <transmission name="r_hip_roll_joint_tran">
    <type>transmission_interface/SimpleTransmission</type>
    <joint name="r_hip_roll_joint">
      <hardwareInterface>hardware_interface/EffortJointInterface</hardwareInterface>
    </joint>
    <actuator name="r_hip_roll_joint_motor">
      <hardwareInterface>EffortJointInterface</hardwareInterface>
      <mechanicalReduction>1</mechanicalReduction>
    </actuator>
  </transmission>
  <!-- right hip roll link -->
  <link name="r_hip_roll_link">
    <visual>
      <origin rpy="0 0 0" xyz="0 0 0"/>
      <geometry>
        <mesh filename="package://huron_description/meshes/r_hip_roll_link.STL" scale="1 1 1"/>
      </geometry>
      <material name="grey"/>
    </visual>
    <collision>
      <origin rpy="0 0 0" xyz="0 0 0"/>
      <geometry>
        <mesh filename="package://huron_description/meshes/r_hip_roll_link.STL" scale="1 1 1"/>
      </geometry>
      <material name="grey"/>
    </collision>
    <inertial>
      <origin rpy="0 0 0" xyz="-0.07196 0.0061152 -0.00052563"/>
      <mass value="1.1884"/>
      <inertia ixx="0.00098222" ixy="9.8947E-08" ixz="9.2484E-09" iyy="0.00097045" iyz="9.7414E-08" izz="0.00092365"/>
    </inertial>
  </link>
  <!-- right hip pitch joint -->
  <joint name="r_hip_pitch_joint" type="revolute">
    <origin rpy="-1.5708 0 -1.5708" xyz="0 0 0"/>
    <parent link="r_hip_roll_link"/>
    <child link="r_hip_pitch_link"/>
    <axis xyz="0 0 1"/>
    <limit effort="1000" lower="-3.1416" upper="3.1416" velocity="3"/>
    <dynamics damping="0.5" friction="100"/>
  </joint>
  <transmission name="r_hip_pitch_joint_tran">
    <type>transmission_interface/SimpleTransmission</type>
    <joint name="r_hip_pitch_joint">
      <hardwareInterface>hardware_interface/EffortJointInterface</hardwareInterface>
    </joint>
    <actuator name="r_hip_pitch_joint_motor">
      <hardwareInterface>EffortJointInterface</hardwareInterface>
      <mechanicalReduction>1</mechanicalReduction>
    </actuator>
  </transmission>
  <!-- right hip pitch link -->
  <link name="r_hip_pitch_link">
    <visual>
      <origin rpy="0 0 0" xyz="0 0 0"/>
      <geometry>
        <mesh filename="package://huron_description/meshes/r_hip_pitch_link.STL" scale="1 1 1"/>
      </geometry>
      <material name="grey"/>
    </visual>
    <collision>
      <origin rpy="0 0 0" xyz="0 0 0"/>
      <geometry>
        <mesh filename="package://huron_description/meshes/r_hip_pitch_link.STL" scale="1 1 1"/>
      </geometry>
      <material name="grey"/>
    </collision>
    <inertial>
      <origin rpy="0 0 0" xyz="0.26753 4.9957E-05 -0.053132"/>
      <mass value="4.2544"/>
      <inertia ixx="0.0034501" ixy="-2.7561E-09" ixz="-0.0019797" iyy="0.010035" iyz="2.5263E-10" izz="0.01009"/>
    </inertial>
  </link>
  <!-- right knee pitch joint -->
  <joint name="r_knee_pitch_joint" type="revolute">
    <origin rpy="0 0 0" xyz="0.512778478308813 4.99999999867273E-05 -1.66647320091612E-05"/>
    <parent link="r_hip_pitch_link"/>
    <child link="r_knee_pitch_link"/>
    <axis xyz="0 0 1"/>
    <limit effort="1000" lower="-3.1416" upper="3.1416" velocity="3"/>
    <dynamics damping="0.5" friction="100"/>
  </joint>
  <transmission name="r_knee_pitch_joint_tran">
    <type>transmission_interface/SimpleTransmission</type>
    <joint name="r_knee_pitch_joint">
      <hardwareInterface>hardware_interface/EffortJointInterface</hardwareInterface>
    </joint>
    <actuator name="r_knee_pitch_joint_motor">
      <hardwareInterface>EffortJointInterface</hardwareInterface>
      <mechanicalReduction>1</mechanicalReduction>
    </actuator>
  </transmission>
  <!-- right knee pitch link -->
  <link name="r_knee_pitch_link">
    <visual>
      <origin rpy="0 0 0" xyz="0 0 0"/>
      <geometry>
        <mesh filename="package://huron_description/meshes/r_knee_pitch_link.STL" scale="1 1 1"/>
      </geometry>
      <material name="grey"/>
    </visual>
    <collision>
      <origin rpy="0 0 0" xyz="0 0 0"/>
      <geometry>
        <mesh filename="package://huron_description/meshes/r_knee_pitch_link.STL" scale="1 1 1"/>
      </geometry>
      <material name="grey"/>
    </collision>
    <inertial>
      <origin rpy="0 0 0" xyz="0.13396 0.00063335 -0.00486"/>
      <mass value="3.4875"/>
      <inertia ixx="0.0064812" ixy="1.2949E-05" ixz="2.8064E-05" iyy="0.019762" iyz="-1.0389E-05" izz="0.017354"/>
    </inertial>
  </link>
  <!-- right ankle pitch joint -->
  <joint name="r_ankle_pitch_joint" type="revolute">
    <origin rpy="0 0 0.0095311367408488" xyz="0.370000000000006 -3.16358749707368E-05 -0.00249999999999918"/>
    <parent link="r_knee_pitch_link"/>
    <child link="r_ankle_pitch_link"/>
    <axis xyz="0 0 1"/>
    <limit effort="1000" lower="-3.1416" upper="3.1416" velocity="3"/>
    <dynamics damping="0.5" friction="100"/>
  </joint>
  <transmission name="r_ankle_pitch_joint_tran">
    <type>transmission_interface/SimpleTransmission</type>
    <joint name="r_ankle_pitch_joint">
      <hardwareInterface>hardware_interface/EffortJointInterface</hardwareInterface>
    </joint>
    <actuator name="r_ankle_pitch_joint_motor">
      <hardwareInterface>EffortJointInterface</hardwareInterface>
      <mechanicalReduction>1</mechanicalReduction>
    </actuator>
  </transmission>
  <!-- right ankle pitch link -->
  <link name="r_ankle_pitch_link">
    <visual>
      <origin rpy="0 0 0" xyz="0 0 0"/>
      <geometry>
        <mesh filename="package://huron_description/meshes/r_ankle_pitch_link.STL" scale="1 1 1"/>
      </geometry>
      <material name="">
        <color rgba="0.77647 0.75686 0.73725 1"/>
      </material>
    </visual>
    <collision>
      <origin rpy="0 0 0" xyz="0 0 0"/>
      <geometry>
        <mesh filename="package://huron_description/meshes/r_ankle_pitch_link.STL" scale="1 1 1"/>
      </geometry>
      <material name="">
        <color rgba="0.77647 0.75686 0.73725 1"/>
      </material>
    </collision>
    <inertial>
      <origin rpy="0 0 0" xyz="-0.029867 0.001045 0.000556"/>
      <mass value="2.4242"/>
      <inertia ixx="0.0025143" ixy="-0.00025651" ixz="1.5321E-12" iyy="0.0045125" iyz="9.9589E-10" izz="0.0049235"/>
    </inertial>
  </link>
  <!-- right ankle roll joint -->
  <joint name="r_ankle_roll_joint" type="revolute">
    <origin rpy="1.57079632679489 0 0" xyz="0 0 0"/>
    <parent link="r_ankle_pitch_link"/>
    <child link="r_ankle_roll_link"/>
    <axis xyz="0 0 1"/>
    <limit effort="1000" lower="-3.1416" upper="3.1416" velocity="3"/>
    <dynamics damping="0.5" friction="100"/>
  </joint>
  <transmission name="r_ankle_roll_joint_tran">
    <type>transmission_interface/SimpleTransmission</type>
    <joint name="r_ankle_roll_joint">
      <hardwareInterface>hardware_interface/EffortJointInterface</hardwareInterface>
    </joint>
    <actuator name="r_ankle_roll_joint_motor">
      <hardwareInterface>EffortJointInterface</hardwareInterface>
      <mechanicalReduction>1</mechanicalReduction>
    </actuator>
  </transmission>
  <!-- right ankle roll link -->
  <link name="r_ankle_roll_link">
    <visual>
      <origin rpy="0 0 0" xyz="0 0 0"/>
      <geometry>
        <mesh filename="package://huron_description/meshes/r_ankle_roll_link.STL" scale="1 1 1"/>
      </geometry>
      <material name="">
        <color rgba="0.77647 0.75686 0.73725 1"/>
      </material>
    </visual>
    <collision>
      <origin rpy="0 0 0" xyz="0 0 0"/>
      <geometry>
        <mesh filename="package://huron_description/meshes/r_ankle_roll_link.STL" scale="1 1 1"/>
      </geometry>
      <material name="">
        <color rgba="0.77647 0.75686 0.73725 1"/>
      </material>
    </collision>
    <inertial>
      <origin rpy="0 0 0" xyz="0.073422 7.2094E-05 0.063933"/>
      <mass value="1.8531"/>
      <inertia ixx="0.0086813" ixy="1.0356E-05" ixz="0.00024346" iyy="0.0084051" iyz="-0.00012301" izz="0.0013018"/>
    </inertial>
  </link>
  <!-- Right foot sensors -->
  <!-- right ft fixed joint 1 -->
  <joint name="r1_ft_fixed" type="revolute">
    <origin rpy="-0.0095317 0.011124 1.5707" xyz="0.096 0.014348 0.13788"/>
    <axis xyz="0 0 1"/>
    <parent link="r_ankle_roll_link"/>
    <child link="r1_foot_ft_link"/>
    <limit effort="100" lower="0" upper="0" velocity="100"/>
  </joint>
  <!-- right foot ft link 1 -->
  <link name="r1_foot_ft_link">
    <visual>
      <origin rpy=" 0 0 0" xyz="0 0 0"/>
      <geometry>
        <mesh filename="package://huron_description/meshes/r_foot_ft.STL" scale="1 1 1"/>
      </geometry>
      <material name="grey"/>
    </visual>
    <collision>
      <origin rpy=" 0 0 0" xyz="0 0 0"/>
      <geometry>
        <mesh filename="package://huron_description/meshes/r_foot_ft.STL" scale="1 1 1"/>
      </geometry>
      <material name="grey"/>
    </collision>
    <inertial>
      <origin rpy="0 0 0" xyz="-9.3029E-06 0.0048381 4.6013E-05"/>
      <mass value="0.0086322"/>
      <inertia ixx="3.8994E-07" ixy="-3.7469E-10" ixz="5.2298E-10" iyy="5.8219E-07" iyz="2.2796E-09" izz="3.4263E-07"/>
    </inertial>
  </link>
  <!-- right ft fixed joint 2 -->
  <joint name="r2_ft_fixed" type="revolute">
    <origin rpy="-0.0095317 0.011124 1.5707" xyz="0.096 -0.020652 0.13788"/>
    <axis xyz="0 0 1"/>
    <parent link="r_ankle_roll_link"/>
    <child link="r2_foot_ft_link"/>
    <limit effort="100" lower="0" upper="0" velocity="100"/>
  </joint>
  <!-- right foot ft link 2 -->
  <link name="r2_foot_ft_link">
    <visual>
      <origin rpy=" 0 0 0" xyz="0 0 0"/>
      <geometry>
        <mesh filename="package://huron_description/meshes/r_foot_ft.STL" scale="1 1 1"/>
      </geometry>
      <material name="grey"/>
    </visual>
    <collision>
      <origin rpy=" 0 0 0" xyz="0 0 0"/>
      <geometry>
        <mesh filename="package://huron_description/meshes/r_foot_ft.STL" scale="1 1 1"/>
      </geometry>
      <material name="grey"/>
    </collision>
    <inertial>
      <origin rpy="0 0 0" xyz="-9.3029E-06 0.0048381 4.6013E-05"/>
      <mass value="0.0086322"/>
      <inertia ixx="3.8994E-07" ixy="-3.7469E-10" ixz="5.2298E-10" iyy="5.8219E-07" iyz="2.2796E-09" izz="3.4263E-07"/>
    </inertial>
  </link>
  <!-- right ft fixed joint 3 -->
  <joint name="r3_ft_fixed" type="revolute">
    <origin rpy="-0.0095317 0.011124 1.5707" xyz="0.096 -0.01683 -0.026"/>
    <axis xyz="0 0 1"/>
    <parent link="r_ankle_roll_link"/>
    <child link="r3_foot_ft_link"/>
    <limit effort="100" lower="0" upper="0" velocity="100"/>
  </joint>
  <!-- right foot ft link 3 -->
  <link name="r3_foot_ft_link">
    <visual>
      <origin rpy=" 0 0 0" xyz="0 0 0"/>
      <geometry>
        <mesh filename="package://huron_description/meshes/r_foot_ft.STL" scale="1 1 1"/>
      </geometry>
      <material name="grey"/>
    </visual>
    <collision>
      <origin rpy=" 0 0 0" xyz="0 0 0"/>
      <geometry>
        <mesh filename="package://huron_description/meshes/r_foot_ft.STL" scale="1 1 1"/>
      </geometry>
      <material name="grey"/>
    </collision>
    <inertial>
      <origin rpy="0 0 0" xyz="-9.3029E-06 0.0048381 4.6013E-05"/>
      <mass value="0.0086322"/>
      <inertia ixx="3.8994E-07" ixy="-3.7469E-10" ixz="5.2298E-10" iyy="5.8219E-07" iyz="2.2796E-09" izz="3.4263E-07"/>
    </inertial>
  </link>
  <!-- right ft fixed joint 4 -->
  <joint name="r4_ft_fixed" type="revolute">
    <origin rpy="-0.0095317 0.011124 1.5707" xyz="0.096 0.016679 -0.026"/>
    <axis xyz="0 0 1"/>
    <parent link="r_ankle_roll_link"/>
    <child link="r4_foot_ft_link"/>
    <limit effort="100" lower="0" upper="0" velocity="100"/>
  </joint>
  <!-- right4 foot ft link 4 -->
  <link name="r4_foot_ft_link">
    <visual>
      <origin rpy=" 0 0 0" xyz="0 0 0"/>
      <geometry>
        <mesh filename="package://huron_description/meshes/r_foot_ft.STL" scale="1 1 1"/>
      </geometry>
      <material name="grey"/>
    </visual>
    <collision>
      <origin rpy=" 0 0 0" xyz="0 0 0"/>
      <geometry>
        <mesh filename="package://huron_description/meshes/r_foot_ft.STL" scale="1 1 1"/>
      </geometry>
      <material name="grey"/>
    </collision>
    <inertial>
      <origin rpy="0 0 0" xyz="-9.3029E-06 0.0048381 4.6013E-05"/>
      <mass value="0.0086322"/>
      <inertia ixx="3.8994E-07" ixy="-3.7469E-10" ixz="5.2298E-10" iyy="5.8219E-07" iyz="2.2796E-09" izz="3.4263E-07"/>
    </inertial>
  </link>
  <!-- right ft fixed joint -->
  <joint name="rv_ft_fixed" type="fixed">
    <origin rpy="0 0 0" xyz="0.0 0.0 0.0"/>
    <axis xyz="0 0 0"/>
    <parent link="r4_foot_ft_link"/>
    <child link="r_foot_v_ft_link"/>
    <limit effort="100" lower="0" upper="0" velocity="100"/>
  </joint>
  <!-- right foot ft link -->
  <link name="r_foot_v_ft_link"/>
  <!-- left hip yaw joint -->
  <joint name="l_hip_yaw_joint" type="revolute">
    <origin rpy="0 0 -0.0062919" xyz="-0.0775 0 -0.14512"/>
    <parent link="base_footprint"/>
    <child link="l_hip_yaw_link"/>
    <axis xyz="0 0 1"/>
    <limit effort="1000" lower="-3.1416" upper="3.1416" velocity="3"/>
    <dynamics damping="0.5" friction="100"/>
  </joint>
  <transmission name="l_hip_yaw_joint_tran">
    <type>transmission_interface/SimpleTransmission</type>
    <joint name="l_hip_yaw_joint">
      <hardwareInterface>hardware_interface/EffortJointInterface</hardwareInterface>
    </joint>
    <actuator name="l_hip_yaw_joint_motor">
      <hardwareInterface>EffortJointInterface</hardwareInterface>
      <mechanicalReduction>1</mechanicalReduction>
    </actuator>
  </transmission>
  <!-- left hip yaw link -->
  <link name="l_hip_yaw_link">
    <visual>
      <origin rpy="0 0 0" xyz="0 0 0"/>
      <geometry>
        <mesh filename="package://huron_description/meshes/l_hip_yaw_link.STL" scale="1 1 1"/>
      </geometry>
      <material name="grey"/>
    </visual>
    <collision>
      <origin rpy="0 0 0" xyz="0 0 0"/>
      <geometry>
        <mesh filename="package://huron_description/meshes/l_hip_yaw_link.STL" scale="1 1 1"/>
      </geometry>
      <material name="grey"/>
    </collision>
    <inertial>
      <origin rpy="0 0 0" xyz="0.00063365 -0.00053469 0.063496"/>
      <mass value="1.6968"/>
      <inertia ixx="0.0022702" ixy="-2.5061E-10" ixz="6.6464E-06" iyy="0.0026746" iyz="-5.1468E-09" izz="0.001238"/>
    </inertial>
  </link>
  <!-- left hip roll joint-->
  <joint name="l_hip_roll_joint" type="revolute">
    <origin rpy="1.5708 0 3.1416" xyz="0 0 0"/>
    <parent link="l_hip_yaw_link"/>
    <child link="l_hip_roll_link"/>
    <axis xyz="0 0 1"/>
    <limit effort="1000" lower="-3.1416" upper="3.1416" velocity="3"/>
    <dynamics damping="0.5" friction="100"/>
  </joint>
  <transmission name="l_hip_roll_joint_tran">
    <type>transmission_interface/SimpleTransmission</type>
    <joint name="l_hip_roll_joint">
      <hardwareInterface>hardware_interface/EffortJointInterface</hardwareInterface>
    </joint>
    <actuator name="l_hip_roll_joint_motor">
      <hardwareInterface>EffortJointInterface</hardwareInterface>
      <mechanicalReduction>1</mechanicalReduction>
    </actuator>
  </transmission>
  <!-- left hip roll link -->
  <link name="l_hip_roll_link">
    <visual>
      <origin rpy="0 0 0" xyz="0 0 0"/>
      <geometry>
        <mesh filename="package://huron_description/meshes/l_hip_roll_link.STL" scale="1 1 1"/>
      </geometry>
      <material name="grey"/>
    </visual>
    <collision>
      <origin rpy="0 0 0" xyz="0 0 0"/>
      <geometry>
        <mesh filename="package://huron_description/meshes/l_hip_roll_link.STL" scale="1 1 1"/>
      </geometry>
      <material name="grey"/>
    </collision>
    <inertial>
      <origin rpy="0 0 0" xyz="0.07196 0.0061153 -0.0005211"/>
      <mass value="1.1884"/>
      <inertia ixx="0.00098222" ixy="-9.9265E-08" ixz="4.9766E-09" iyy="0.00097045" iyz="-9.7282E-08" izz="0.00092365"/>
    </inertial>
  </link>
  <!-- left hip pitch joint -->
  <joint name="l_hip_pitch_joint" type="revolute">
    <origin rpy="-1.5707963267949 0 -1.5707963267949" xyz="0 0 0"/>
    <parent link="l_hip_roll_link"/>
    <child link="l_hip_pitch_link"/>
    <axis xyz="0 0 1"/>
    <limit effort="1000" lower="-3.1416" upper="3.1416" velocity="3"/>
    <dynamics damping="0.5" friction="100"/>
  </joint>
  <transmission name="l_hip_pitch_joint_tran">
    <type>transmission_interface/SimpleTransmission</type>
    <joint name="l_hip_pitch_joint">
      <hardwareInterface>hardware_interface/EffortJointInterface</hardwareInterface>
    </joint>
    <actuator name="l_hip_pitch_joint_motor">
      <hardwareInterface>EffortJointInterface</hardwareInterface>
      <mechanicalReduction>1</mechanicalReduction>
    </actuator>
  </transmission>
  <!-- left hip pitch link -->
  <link name="l_hip_pitch_link">
    <visual>
      <origin rpy="0 0 0" xyz="0 0 0"/>
      <geometry>
        <mesh filename="package://huron_description/meshes/l_hip_pitch_link.STL" scale="1 1 1"/>
      </geometry>
      <material name="grey"/>
    </visual>
    <collision>
      <origin rpy="0 0 0" xyz="0 0 0"/>
      <geometry>
        <mesh filename="package://huron_description/meshes/l_hip_pitch_link.STL" scale="1 1 1"/>
      </geometry>
      <material name="grey"/>
    </collision>
    <inertial>
      <origin rpy="0 0 0" xyz="0.26603 4.6212E-05 0.053152"/>
      <mass value="4.2544"/>
      <inertia ixx="0.0034527" ixy="-3.1046E-08" ixz="0.0019797" iyy="0.010032" iyz="-1.4492E-10" izz="0.01009"/>
    </inertial>
  </link>
  <!-- left knee pitch joint -->
  <joint name="l_knee_pitch_joint" type="revolute">
    <origin rpy="0 0 0" xyz="0.511278478308803 4.99999997527478E-05 1.66647320021251E-05"/>
    <parent link="l_hip_pitch_link"/>
    <child link="l_knee_pitch_link"/>
    <axis xyz="0 0 1"/>
    <limit effort="1000" lower="-3.1416" upper="3.1416" velocity="3"/>
    <dynamics damping="0.5" friction="100"/>
  </joint>
  <transmission name="l_knee_pitch_joint_tran">
    <type>transmission_interface/SimpleTransmission</type>
    <joint name="l_knee_pitch_joint">
      <hardwareInterface>hardware_interface/EffortJointInterface</hardwareInterface>
    </joint>
    <actuator name="l_knee_pitch_joint_motor">
      <hardwareInterface>EffortJointInterface</hardwareInterface>
      <mechanicalReduction>1</mechanicalReduction>
    </actuator>
  </transmission>
  <!-- left knee pitch link -->
  <link name="l_knee_pitch_link">
    <visual>
      <origin rpy="0 0 0" xyz="0 0 0"/>
      <geometry>
        <mesh filename="package://huron_description/meshes/l_knee_pitch_link.STL" scale="1 1 1"/>
      </geometry>
      <material name="grey"/>
    </visual>
    <collision>
      <origin rpy="0 0 0" xyz="0 0 0"/>
      <geometry>
        <mesh filename="package://huron_description/meshes/l_knee_pitch_link.STL" scale="1 1 1"/>
      </geometry>
      <material name="grey"/>
    </collision>
    <inertial>
      <origin rpy="0 0 0" xyz="0.13395 0.00068098 0.00486"/>
      <mass value="3.4875"/>
      <inertia ixx="0.0064808" ixy="1.3685E-05" ixz="-2.8221E-05" iyy="0.019763" iyz="1.0351E-05" izz="0.017354"/>
    </inertial>
  </link>
  <!-- left ankle pitch joint -->
  <joint name="l_ankle_pitch_joint" type="revolute">
    <origin rpy="0 0 0.0249371730038869" xyz="0.370000000000016 3.16358752296964E-05 0.00249999999999911"/>
    <parent link="l_knee_pitch_link"/>
    <child link="l_ankle_pitch_link"/>
    <axis xyz="0 0 1"/>
    <limit effort="1000" lower="-3.1416" upper="3.1416" velocity="3"/>
    <dynamics damping="0.5" friction="100"/>
  </joint>
  <transmission name="l_ankle_pitch_joint_tran">
    <type>transmission_interface/SimpleTransmission</type>
    <joint name="l_ankle_pitch_joint">
      <hardwareInterface>hardware_interface/EffortJointInterface</hardwareInterface>
    </joint>
    <actuator name="l_ankle_pitch_joint_motor">
      <hardwareInterface>EffortJointInterface</hardwareInterface>
      <mechanicalReduction>1</mechanicalReduction>
    </actuator>
  </transmission>
  <!-- left ankle pitch link -->
  <link name="l_ankle_pitch_link">
    <visual>
      <origin rpy="0 0 0" xyz="0 0 0"/>
      <geometry>
        <mesh filename="package://huron_description/meshes/l_ankle_pitch_link.STL" scale="1 1 1"/>
      </geometry>
      <material name="">
        <color rgba="0.89804 0.91765 0.92941 1"/>
      </material>
    </visual>
    <collision>
      <origin rpy="0 0 0" xyz="0 0 0"/>
      <geometry>
        <mesh filename="package://huron_description/meshes/l_ankle_pitch_link.STL" scale="1 1 1"/>
      </geometry>
      <material name="">
        <color rgba="0.89804 0.91765 0.92941 1"/>
      </material>
    </collision>
    <inertial>
      <origin rpy="0 0 0" xyz="-0.029808 0.001045 3.1135E-08"/>
      <mass value="2.4242"/>
      <inertia ixx="0.0025143" ixy="-0.00025651" ixz="1.1648E-12" iyy="0.0045125" iyz="6.7198E-10" izz="0.0049235"/>
    </inertial>
  </link>
  <!-- left ankle roll pitch -->
  <joint name="l_ankle_roll_joint" type="revolute">
    <origin rpy="1.57079632679489 0 0" xyz="0 0 0"/>
    <parent link="l_ankle_pitch_link"/>
    <child link="l_ankle_roll_link"/>
    <axis xyz="0 0 1"/>
    <limit effort="1000" lower="-3.1416" upper="3.1416" velocity="3"/>
    <dynamics damping="0.5" friction="100"/>
  </joint>
  <transmission name="l_ankle_roll_joint_tran">
    <type>transmission_interface/SimpleTransmission</type>
    <joint name="l_ankle_roll_joint">
      <hardwareInterface>hardware_interface/EffortJointInterface</hardwareInterface>
    </joint>
    <actuator name="l_ankle_roll_joint_motor">
      <hardwareInterface>EffortJointInterface</hardwareInterface>
      <mechanicalReduction>1</mechanicalReduction>
    </actuator>
  </transmission>
  <!-- left ankle roll link -->
  <link name="l_ankle_roll_link">
    <visual>
      <origin rpy="0 0 0" xyz="0 0 0"/>
      <geometry>
        <mesh filename="package://huron_description/meshes/l_ankle_roll_link.STL" scale="1 1 1"/>
      </geometry>
      <material name="">
        <color rgba="0.77647 0.75686 0.73725 1"/>
      </material>
    </visual>
    <collision>
      <origin rpy="0 0 0" xyz="0 0 0"/>
      <geometry>
        <mesh filename="package://huron_description/meshes/l_ankle_roll_link.STL" scale="1 1 1"/>
      </geometry>
      <material name="">
        <color rgba="0.77647 0.75686 0.73725 1"/>
      </material>
    </collision>
    <inertial>
      <origin rpy="0 0 0" xyz="0.073422 -5.3261E-05 0.063946"/>
      <mass value="1.8533"/>
      <inertia ixx="0.008682" ixy="-1.0255E-05" ixz="0.00024351" iyy="0.0084057" iyz="0.00012332" izz="0.0013019"/>
    </inertial>
  </link>
  <!-- left ft fixed joint 1 -->
  <joint name="l1_ft_fixed" type="revolute">
    <origin rpy="-0.024938 0.00629 1.5706" xyz="0.095 0.020682 0.13788"/>
    <axis xyz="0 0 1"/>
    <parent link="l_ankle_roll_link"/>
    <child link="l1_foot_ft_link"/>
    <limit effort="100" lower="0" upper="0" velocity="100"/>
  </joint>
  <!-- left foot ft link 1 -->
  <link name="l1_foot_ft_link">
    <visual>
      <origin rpy=" 0 0 0" xyz="0 0 0"/>
      <geometry>
        <mesh filename="package://huron_description/meshes/r_foot_ft.STL" scale="1 1 1"/>
      </geometry>
      <material name="grey"/>
    </visual>
    <collision>
      <origin rpy=" 0 0 0" xyz="0 0 0"/>
      <geometry>
        <mesh filename="package://huron_description/meshes/r_foot_ft.STL" scale="1 1 1"/>
      </geometry>
      <material name="grey"/>
    </collision>
    <inertial>
      <origin rpy="0 0 0" xyz="6.5681E-06 0.0048368 0.00012069"/>
      <mass value="0.0086322"/>
      <inertia ixx="3.8994E-07" ixy="2.5351E-10" ixz="3.0416E-10" iyy="5.8206E-07" iyz="5.9744E-09" izz="3.4276E-07"/>
    </inertial>
  </link>
  <!-- left ft fixed joint 2 -->
  <joint name="l2_ft_fixed" type="revolute">
    <origin rpy="-0.024938 0.00629 1.5706" xyz="0.095 -0.014318 0.13788"/>
    <axis xyz="0 0 1"/>
    <parent link="l_ankle_roll_link"/>
    <child link="l2_foot_ft_link"/>
    <limit effort="100" lower="0" upper="0" velocity="100"/>
  </joint>
  <!-- left foot ft link 2 -->
  <link name="l2_foot_ft_link">
    <visual>
      <origin rpy=" 0 0 0" xyz="0 0 0"/>
      <geometry>
        <mesh filename="package://huron_description/meshes/r_foot_ft.STL" scale="1 1 1"/>
      </geometry>
      <material name="grey"/>
    </visual>
    <collision>
      <origin rpy=" 0 0 0" xyz="0 0 0"/>
      <geometry>
        <mesh filename="package://huron_description/meshes/r_foot_ft.STL" scale="1 1 1"/>
      </geometry>
      <material name="grey"/>
    </collision>
    <inertial>
      <origin rpy="0 0 0" xyz="6.56809560273253E-06 0.00483682139671537 0.000120685375128327"/>
      <mass value="0.00863223621815319"/>
      <inertia ixx="3.89940248965647E-07" ixy="2.53506346419819E-10" ixz="3.04161588773098E-10" iyy="5.82064646347941E-07" iyz="5.97441467814794E-09" izz="3.42755265424868E-07"/>
    </inertial>
  </link>
  <!-- left ft fixed joint 3 -->
  <joint name="l3_ft_fixed" type="revolute">
    <origin rpy="-0.024938 0.00629 1.5706" xyz="0.095 -0.016649 -0.026"/>
    <axis xyz="0 0 1"/>
    <parent link="l_ankle_roll_link"/>
    <child link="l3_foot_ft_link"/>
    <limit effort="100" lower="0" upper="0" velocity="100"/>
  </joint>
  <!-- left foot ft link 3 -->
  <link name="l3_foot_ft_link">
    <visual>
      <origin rpy=" 0 0 0" xyz="0 0 0"/>
      <geometry>
        <mesh filename="package://huron_description/meshes/r_foot_ft.STL" scale="1 1 1"/>
      </geometry>
      <material name="grey"/>
    </visual>
    <collision>
      <origin rpy=" 0 0 0" xyz="0 0 0"/>
      <geometry>
        <mesh filename="package://huron_description/meshes/r_foot_ft.STL" scale="1 1 1"/>
      </geometry>
      <material name="grey"/>
    </collision>
    <inertial>
      <origin rpy="0 0 0" xyz="6.56809560273253E-06 0.00483682139671548 0.000120685375128382"/>
      <mass value="0.00863223621815319"/>
      <inertia ixx="3.89940248965648E-07" ixy="2.53506346419837E-10" ixz="3.04161588773088E-10" iyy="5.82064646347941E-07" iyz="5.97441467814795E-09" izz="3.42755265424868E-07"/>
    </inertial>
  </link>
  <!-- left ft fixed joint 4 -->
  <joint name="l4_ft_fixed" type="revolute">
    <origin rpy="-0.024938 0.00629 1.5706" xyz="0.095 0.01686 -0.026"/>
    <axis xyz="0 0 1"/>
    <parent link="l_ankle_roll_link"/>
    <child link="l4_foot_ft_link"/>
    <limit effort="100" lower="0" upper="0" velocity="100"/>
  </joint>
  <!-- left foot ft link 4 -->
  <link name="l4_foot_ft_link">
    <visual>
      <origin rpy=" 0 0 0" xyz="0 0 0"/>
      <geometry>
        <mesh filename="package://huron_description/meshes/r_foot_ft.STL" scale="1 1 1"/>
      </geometry>
      <material name="grey"/>
    </visual>
    <collision>
      <origin rpy=" 0 0 0" xyz="0 0 0"/>
      <geometry>
        <mesh filename="package://huron_description/meshes/r_foot_ft.STL" scale="1 1 1"/>
      </geometry>
      <material name="grey"/>
    </collision>
    <inertial>
      <origin rpy="0 0 0" xyz="6.5681E-06 0.0048368 0.00012069"/>
      <mass value="0.0086322"/>
      <inertia ixx="3.8994E-07" ixy="2.5351E-10" ixz="3.0416E-10" iyy="5.8206E-07" iyz="5.9744E-09" izz="3.4276E-07"/>
    </inertial>
  </link>
  <!-- left ft fixed joint -->
  <joint name="lv_ft_fixed" type="fixed">
    <origin rpy="0 -1.570796327 0" xyz="0.045 0.0 0.0"/>
    <parent link="l4_foot_ft_link"/>
    <child link="l_foot_v_ft_link"/>
  </joint>
  <!-- left foot ft link -->
  <link name="l_foot_v_ft_link"/>
</robot>

