<?xml version="1.0" ?>
<!-- =================================================================================== -->
<!-- |    This document was autogenerated by xacro from huron.xacro                    | -->
<!-- |    EDITING THIS FILE BY HAND IS NOT RECOMMENDED                                 | -->
<!-- =================================================================================== -->
<robot name="huron">
  <material name="black">
    <color rgba="0.0 0.0 0.0 1.0"/>
  </material>
  <material name="blue">
    <color rgba="0.0 0.0 0.8 1.0"/>
  </material>
  <material name="green">
    <color rgba="0.0 0.8 0.0 1.0"/>
  </material>
  <material name="grey">
    <color rgba="0.75294 0.75294 0.75294 1"/>
  </material>
  <material name="orange">
    <color rgba="1.0 0.4235294117647059 0.0392156862745098 1.0"/>
  </material>
  <material name="brown">
    <color rgba="0.8705882352941177 0.8117647058823529 0.7647058823529411 1.0"/>
  </material>
  <material name="red">
    <color rgba="0.8 0.0 0.0 1.0"/>
  </material>
  <material name="white">
    <color rgba="1.0 1.0 1.0 1.0"/>
  </material>
  <!-- Right leg -->
  <!-- Right foot sensors -->
  <!-- ros_control plugin -->
  <gazebo>
    <plugin filename="libgazebo_ros_control.so" name="gazebo_ros_control">
      <robotNamespace>/huron</robotNamespace>
    </plugin>
  </gazebo>
  <gazebo>
    <plugin filename="libgazebo_ros_p3d.so" name="ground_truth">
      <frameName>map</frameName>
      <bodyName>base_link</bodyName>
      <topicName>/huron/odom</topicName>
      <updateRate>100.0</updateRate>
    </plugin>
  </gazebo>
  <!-- imu sensor -->
  <gazebo reference="imu_link">
    <gravity>true</gravity>
    <sensor name="imu_sensor" type="imu">
      <always_on>true</always_on>
      <update_rate>100</update_rate>
      <visualize>true</visualize>
      <topic>/huron/sensor/imu</topic>
      <plugin filename="libgazebo_ros_imu_sensor.so" name="imu_plugin">
        <topicName>huron/sensor/imu</topicName>
        <bodyName>imu_link</bodyName>
        <updateRateHZ>10.0</updateRateHZ>
        <gaussianNoise>0.0</gaussianNoise>
        <xyzOffset>0 0 0</xyzOffset>
        <rpyOffset>0 0 0</rpyOffset>
        <frameName>imu_link</frameName>
      </plugin>
      <pose>0 0 0 0 0 0</pose>
    </sensor>
  </gazebo>
  <gazebo reference="r1_ft_fixed">
    <provideFeedback>true</provideFeedback>
  </gazebo>
  <gazebo>
    <plugin filename="libgazebo_ros_ft_sensor.so" name="r1_ft_sensor">
      <updateRate>100.0</updateRate>
      <topicName>/huron/sensor/r1_ft_sensor</topicName>
      <jointName>r1_ft_fixed</jointName>
      <gaussianNoise>0.0</gaussianNoise>
    </plugin>
  </gazebo>
  <gazebo reference="r2_ft_fixed">
    <provideFeedback>true</provideFeedback>
  </gazebo>
  <gazebo>
    <plugin filename="libgazebo_ros_ft_sensor.so" name="r2_ft_sensor">
      <updateRate>100.0</updateRate>
      <topicName>/huron/sensor/r2_ft_sensor</topicName>
      <jointName>r2_ft_fixed</jointName>
      <gaussianNoise>0.0</gaussianNoise>
    </plugin>
  </gazebo>
  <gazebo reference="r3_ft_fixed">
    <provideFeedback>true</provideFeedback>
  </gazebo>
  <gazebo>
    <plugin filename="libgazebo_ros_ft_sensor.so" name="r3_ft_sensor">
      <updateRate>100.0</updateRate>
      <topicName>/huron/sensor/r3_ft_sensor</topicName>
      <jointName>r3_ft_fixed</jointName>
      <gaussianNoise>0.0</gaussianNoise>
    </plugin>
  </gazebo>
  <gazebo reference="r4_ft_fixed">
    <provideFeedback>true</provideFeedback>
  </gazebo>
  <gazebo>
    <plugin filename="libgazebo_ros_ft_sensor.so" name="r4_ft_sensor">
      <updateRate>100.0</updateRate>
      <topicName>/huron/sensor/r4_ft_sensor</topicName>
      <jointName>r4_ft_fixed</jointName>
      <gaussianNoise>0.0</gaussianNoise>
    </plugin>
  </gazebo>
  <gazebo reference="l1_ft_fixed">
    <provideFeedback>true</provideFeedback>
  </gazebo>
  <gazebo>
    <plugin filename="libgazebo_ros_ft_sensor.so" name="l1_ft_sensor">
      <updateRate>100.0</updateRate>
      <topicName>/huron/sensor/l1_ft_sensor</topicName>
      <jointName>l1_ft_fixed</jointName>
      <gaussianNoise>0.0</gaussianNoise>
    </plugin>
  </gazebo>
  <gazebo reference="l2_ft_fixed">
    <provideFeedback>true</provideFeedback>
  </gazebo>
  <gazebo>
    <plugin filename="libgazebo_ros_ft_sensor.so" name="l2_ft_sensor">
      <updateRate>100.0</updateRate>
      <topicName>/huron/sensor/l2_ft_sensor</topicName>
      <jointName>l2_ft_fixed</jointName>
      <gaussianNoise>0.0</gaussianNoise>
    </plugin>
  </gazebo>
  <gazebo reference="l3_ft_fixed">
    <provideFeedback>true</provideFeedback>
  </gazebo>
  <gazebo>
    <plugin filename="libgazebo_ros_ft_sensor.so" name="l3_ft_sensor">
      <updateRate>100.0</updateRate>
      <topicName>/huron/sensor/l3_ft_sensor</topicName>
      <jointName>l3_ft_fixed</jointName>
      <gaussianNoise>0.0</gaussianNoise>
    </plugin>
  </gazebo>
  <gazebo reference="l4_ft_fixed">
    <provideFeedback>true</provideFeedback>
  </gazebo>
  <gazebo>
    <plugin filename="libgazebo_ros_ft_sensor.so" name="r4_ft_sensor">
      <updateRate>100.0</updateRate>
      <topicName>/huron/sensor/l4_ft_sensor</topicName>
      <jointName>l4_ft_fixed</jointName>
      <gaussianNoise>0.0</gaussianNoise>
    </plugin>
  </gazebo>
  <!-- World -->
  <gazebo reference="world"/>
  <!-- Map -->
  <gazebo reference="map"/>
  <!-- Base -->
  <gazebo reference="base_link"/>
  <!-- IMU -->
  <gazebo reference="imu_link"/>
  <!-- Body-->
  <gazebo reference="base_footprint">
    <mu1>0.2</mu1>
    <mu2>0.2</mu2>
    <material>Gazebo/Grey</material>
    <selfCollide>false</selfCollide>
  </gazebo>
  <!-- Battery -->
  <gazebo reference="battery_link">
    <material>Gazebo/SkyBlue</material>
    <selfCollide>false</selfCollide>
  </gazebo>
  <!-- Left Leg -->
  <gazebo reference="l_hip_yaw_link">
    <mu1>0.2</mu1>
    <mu2>0.2</mu2>
    <material>Gazebo/Grey</material>
    <selfCollide>false</selfCollide>
  </gazebo>
  <gazebo reference="l_hip_roll_link">
    <mu1>0.2</mu1>
    <mu2>0.2</mu2>
    <material>Gazebo/Grey</material>
    <selfCollide>false</selfCollide>
  </gazebo>
  <gazebo reference="l_hip_pitch_link">
    <mu1>0.2</mu1>
    <mu2>0.2</mu2>
    <material>Gazebo/Grey</material>
    <selfCollide>false</selfCollide>
  </gazebo>
  <gazebo reference="l_knee_pitch_link">
    <mu1>0.2</mu1>
    <mu2>0.2</mu2>
    <material>Gazebo/Grey</material>
    <selfCollide>false</selfCollide>
  </gazebo>
  <gazebo reference="l_ankle_pitch_link">
    <mu1>0.2</mu1>
    <mu2>0.2</mu2>
    <material>Gazebo/Grey</material>
    <selfCollide>false</selfCollide>
  </gazebo>
  <gazebo reference="l_ankle_roll_link">
    <!-- <kp>100000.0</kp> -->
    <!-- <kd>100.0</kd> -->
    <mu1>0.9</mu1>
    <mu2>0.9</mu2>
    <!--<maxContacts>30</maxContacts>-->
    <!-- <fdir1>1 0 0</fdir1> -->
    <!-- <maxVel>1.0</maxVel> -->
    <!-- <minDepth>0.001</minDepth> -->
    <material>Gazebo/Blue</material>
  </gazebo>
  <gazebo reference="l1_foot_ft_link">
    <kp>1e7</kp>
    <kd>1e5</kd>
    <mu1>1.5</mu1>
    <mu2>1.5</mu2>
    <!--<maxContacts>30</maxContacts>-->
    <fdir1>1 0 0</fdir1>
    <maxVel>0.0</maxVel>
    <minDepth>0.001</minDepth>
    <material>Gazebo/Orange</material>
  </gazebo>
  <gazebo reference="l2_foot_ft_link">
    <kp>1e7</kp>
    <kd>1e5</kd>
    <mu1>1.5</mu1>
    <mu2>1.5</mu2>
    <!--<maxContacts>30</maxContacts>-->
    <fdir1>1 0 0</fdir1>
    <maxVel>0.0</maxVel>
    <minDepth>0.001</minDepth>
    <material>Gazebo/Orange</material>
  </gazebo>
  <gazebo reference="l3_foot_ft_link">
    <kp>1e7</kp>
    <kd>1e5</kd>
    <mu1>1.5</mu1>
    <mu2>1.5</mu2>
    <!--<maxContacts>30</maxContacts>-->
    <fdir1>1 0 0</fdir1>
    <maxVel>0.0</maxVel>
    <minDepth>0.001</minDepth>
    <material>Gazebo/Orange</material>
  </gazebo>
  <gazebo reference="l4_foot_ft_link">
    <kp>1e7</kp>
    <kd>1e5</kd>
    <mu1>1.5</mu1>
    <mu2>1.5</mu2>
    <!--<maxContacts>30</maxContacts>-->
    <fdir1>1 0 0</fdir1>
    <maxVel>0.0</maxVel>
    <minDepth>0.001</minDepth>
    <material>Gazebo/Orange</material>
  </gazebo>
  <!-- Right Leg -->
  <gazebo reference="r_hip_yaw_link">
    <mu1>0.2</mu1>
    <mu2>0.2</mu2>
    <material>Gazebo/Grey</material>
    <selfCollide>false</selfCollide>
  </gazebo>
  <gazebo reference="r_hip_roll_link">
    <mu1>0.2</mu1>
    <mu2>0.2</mu2>
    <material>Gazebo/Grey</material>
    <selfCollide>false</selfCollide>
  </gazebo>
  <gazebo reference="r_hip_pitch_link">
    <mu1>0.2</mu1>
    <mu2>0.2</mu2>
    <material>Gazebo/Grey</material>
    <selfCollide>false</selfCollide>
  </gazebo>
  <gazebo reference="r_knee_pitch_link">
    <mu1>0.2</mu1>
    <mu2>0.2</mu2>
    <material>Gazebo/Grey</material>
    <selfCollide>false</selfCollide>
  </gazebo>
  <gazebo reference="r_ankle_pitch_link">
    <mu1>0.2</mu1>
    <mu2>0.2</mu2>
    <material>Gazebo/Grey</material>
    <selfCollide>false</selfCollide>
  </gazebo>
  <gazebo reference="r_ankle_roll_link">
    <!-- <kp>100000.0</kp> -->
    <!-- <kd>100.0</kd> -->
    <mu1>0.9</mu1>
    <mu2>0.9</mu2>
    <!--<maxContacts>30</maxContacts>-->
    <!-- <fdir1>1 0 0</fdir1> -->
    <!--  <maxVel>1.0</maxVel>  -->
    <!-- <minDepth>0.0001</minDepth> -->
    <material>Gazebo/Blue</material>
  </gazebo>
  <gazebo reference="r1_foot_ft_link">
    <kp>1e7</kp>
    <kd>1e5</kd>
    <mu1>1.5</mu1>
    <mu2>1.5</mu2>
    <!--<maxContacts>30</maxContacts>-->
    <fdir1>1 0 0</fdir1>
    <maxVel>0.0</maxVel>
    <minDepth>0.001</minDepth>
    <material>Gazebo/Orange</material>
  </gazebo>
  <gazebo reference="r2_foot_ft_link">
    <kp>1e7</kp>
    <kd>1e5</kd>
    <mu1>1.5</mu1>
    <mu2>1.5</mu2>
    <!--<maxContacts>30</maxContacts>-->
    <fdir1>1 0 0</fdir1>
    <maxVel>0.0</maxVel>
    <minDepth>0.001</minDepth>
    <material>Gazebo/Orange</material>
  </gazebo>
  <gazebo reference="r3_foot_ft_link">
    <kp>1e7</kp>
    <kd>1e5</kd>
    <mu1>1.5</mu1>
    <mu2>1.5</mu2>
    <!--<maxContacts>30</maxContacts>-->
    <fdir1>1 0 0</fdir1>
    <maxVel>0.0</maxVel>
    <minDepth>0.001</minDepth>
    <material>Gazebo/Orange</material>
  </gazebo>
  <gazebo reference="r4_foot_ft_link">
    <kp>1e7</kp>
    <kd>1e5</kd>
    <mu1>1.5</mu1>
    <mu2>1.5</mu2>
    <!--<maxContacts>30</maxContacts>-->
    <fdir1>1 0 0</fdir1>
    <maxVel>0.0</maxVel>
    <minDepth>0.001</minDepth>
    <material>Gazebo/Orange</material>
  </gazebo>
  <!-- Used for fixing robot -->
  <!--<link name="world"></link> 
    <joint name="world_fixed" type="fixed">
        <origin xyz="0 0 0.764" rpy="0 0 0"/>
        <parent link="world"/>
        <child link="base_link"/>
    </joint> -->
  <link name="base_link"/>
  <joint name="base_fixed" type="fixed">
    <origin rpy="0 0 0" xyz="0 0 0"/>
    <parent link="base_link"/>
    <child link="base_footprint"/>
  </joint>
  <!-- base_link -->
  <link name="base_footprint">
    <visual>
      <origin rpy="0 0 0" xyz="0 0 0"/>
      <geometry>
        <mesh filename="package://huron_description/meshes/base_link.STL" scale="1 1 1"/>
      </geometry>
      <material name="grey"/>
    </visual>
    <collision>
      <origin rpy="0 0 0" xyz="0 0 0"/>
      <geometry>
        <mesh filename="package://huron_description/meshes/base_link.STL" scale="1 1 1"/>
      </geometry>
      <material name="grey"/>
    </collision>
    <inertial>
      <origin rpy="0 0 0" xyz="-1.3585E-07 5.07E-07 0.026975"/>
      <mass value="3.4072"/>
      <inertia ixx="0.00319" ixy="-1.7776E-09" ixz="-1.7316E-09" iyy="0.010531" iyz="6.4623E-09" izz="0.012315"/>
    </inertial>
  </link>
  <!-- Battery -->
  <link name="battery_link">
    <visual>
      <origin rpy="0 0 0" xyz="0 0 0"/>
      <geometry>
        <box size="0.065 0.188 0.151"/>
      </geometry>
      <material name="blue"/>
    </visual>
    <collision>
      <origin rpy="0 0 0" xyz="0 0 0"/>
      <geometry>
        <box size="0.065 0.188 0.151"/>
      </geometry>
      <material name="blue"/>
    </collision>
    <inertial>
      <origin rpy="0 0 0" xyz="0 0 0"/>
      <mass value="3.90089"/>
      <inertia ixx="0.01890143742" ixy="0" ixz="0" iyy="0.0128628597" iyz="0" izz="0.008785454428"/>
    </inertial>
  </link>
  <joint name="battery_fixed" type="fixed">
    <origin rpy="0 0 0" xyz="0 0 0.0895"/>
    <parent link="base_footprint"/>
    <child link="battery_link"/>
  </joint>
  <!-- imu joint -->
  <joint name="imu_fixed" type="fixed">
    <origin rpy="0 0 0" xyz="0 0 0"/>
    <parent link="base_footprint"/>
    <child link="imu_link"/>
  </joint>
  <link name="imu_link"/>
  <!-- right hip yaw joint -->
  <joint name="r_hip_yaw_joint" type="revolute">
    <origin rpy="0 0 3.141592654" xyz="0.0775 0 -0.14512"/>
    <parent link="base_footprint"/>
    <child link="r_hip_yaw_link"/>
    <axis xyz="0 0 1"/>
    <limit effort="1000" lower="-3.1416" upper="3.1416" velocity="3"/>
    <dynamics damping="0.5" friction="8"/>
  </joint>
  <transmission name="r_hip_yaw_joint_tran">
    <type>transmission_interface/SimpleTransmission</type>
    <joint name="r_hip_yaw_joint">
      <hardwareInterface>hardware_interface/EffortJointInterface</hardwareInterface>
    </joint>
    <actuator name="r_hip_yaw_joint_motor">
      <hardwareInterface>EffortJointInterface</hardwareInterface>
      <mechanicalReduction>1</mechanicalReduction>
    </actuator>
  </transmission>
  <!-- right hip yaw link -->
  <link name="r_hip_yaw_link">
    <visual>
      <origin rpy="0 0 0" xyz="0 0 0"/>
      <geometry>
        <mesh filename="package://huron_description/meshes/r_hip_yaw_link.STL" scale="1 1 1"/>
      </geometry>
      <material name="grey"/>
    </visual>
    <collision>
      <origin rpy="0 0 0" xyz="0 0 0"/>
      <geometry>
        <mesh filename="package://huron_description/meshes/r_hip_yaw_link.STL" scale="1 1 1"/>
      </geometry>
      <material name="grey"/>
    </collision>
    <inertial>
      <origin rpy="0 0 0" xyz="0.0006244 0.00052023 0.063505"/>
      <mass value="1.6968"/>
      <inertia ixx="0.0022729" ixy="-5.6494E-10" ixz="6.6464E-06" iyy="0.0026746" iyz="5.69E-09" izz="0.0012354"/>
    </inertial>
  </link>
  <!-- right hip roll joint-->
  <joint name="r_hip_roll_joint" type="revolute">
    <origin rpy="1.570796327 0 0" xyz="0 0 0"/>
    <parent link="r_hip_yaw_link"/>
    <child link="r_hip_roll_link"/>
    <axis xyz="0 0 1"/>
    <limit effort="1000" lower="-0.5236" upper="0.01" velocity="3"/>
    <dynamics damping="0.5" friction="8"/>
  </joint>
  <transmission name="r_hip_roll_joint_tran">
    <type>transmission_interface/SimpleTransmission</type>
    <joint name="r_hip_roll_joint">
      <hardwareInterface>hardware_interface/EffortJointInterface</hardwareInterface>
    </joint>
    <actuator name="r_hip_roll_joint_motor">
      <hardwareInterface>EffortJointInterface</hardwareInterface>
      <mechanicalReduction>1</mechanicalReduction>
    </actuator>
  </transmission>
  <!-- right hip roll link -->
  <link name="r_hip_roll_link">
    <visual>
      <origin rpy="0 0 0" xyz="0 0 0"/>
      <geometry>
        <mesh filename="package://huron_description/meshes/r_hip_roll_link.STL" scale="1 1 1"/>
      </geometry>
      <material name="grey"/>
    </visual>
    <collision>
      <origin rpy="0 0 0" xyz="0 0 0"/>
      <geometry>
        <mesh filename="package://huron_description/meshes/r_hip_roll_link.STL" scale="1 1 1"/>
      </geometry>
      <material name="grey"/>
    </collision>
    <inertial>
      <origin rpy="0 0 0" xyz="-0.071945 0.0061152 -0.00052563"/>
      <mass value="1.1884"/>
      <inertia ixx="0.00098222" ixy="9.8944E-08" ixz="9.2479E-09" iyy="0.00097045" iyz="9.7418E-08" izz="0.00092365"/>
    </inertial>
  </link>
  <!-- right hip pitch joint -->
  <joint name="r_hip_pitch_joint" type="revolute">
    <origin rpy="-1.570796327 0 -1.570796327" xyz="-1.6665E-05 -0.0165 -5E-05"/>
    <parent link="r_hip_roll_link"/>
    <child link="r_hip_pitch_link"/>
    <axis xyz="0 0 1"/>
    <limit effort="1000" lower="-1.2217" upper="1.2217" velocity="3"/>
    <dynamics damping="0.5" friction="8"/>
  </joint>
  <transmission name="r_hip_pitch_joint_tran">
    <type>transmission_interface/SimpleTransmission</type>
    <joint name="r_hip_pitch_joint">
      <hardwareInterface>hardware_interface/EffortJointInterface</hardwareInterface>
    </joint>
    <actuator name="r_hip_pitch_joint_motor">
      <hardwareInterface>EffortJointInterface</hardwareInterface>
      <mechanicalReduction>1</mechanicalReduction>
    </actuator>
  </transmission>
  <!-- right hip pitch link -->
  <link name="r_hip_pitch_link">
    <visual>
      <origin rpy="0 0 0" xyz="0 0 0"/>
      <geometry>
        <mesh filename="package://huron_description/meshes/r_hip_pitch_link.STL" scale="1 1 1"/>
      </geometry>
      <material name="grey"/>
    </visual>
    <collision>
      <origin rpy="0 0 0" xyz="0 0 0"/>
      <geometry>
        <mesh filename="package://huron_description/meshes/r_hip_pitch_link.STL" scale="1 1 1"/>
      </geometry>
      <material name="grey"/>
    </collision>
    <inertial>
      <origin rpy="0 0 0" xyz="0.25103 -6.5307E-08 -0.05311"/>
      <mass value="4.2544"/>
      <inertia ixx="0.0034501" ixy="1.1101E-07" ixz="-0.0019797" iyy="0.010035" iyz="-7.0796E-10" izz="0.01009"/>
    </inertial>
  </link>
  <!-- right knee pitch joint -->
  <joint name="r_knee_pitch_joint" type="revolute">
    <origin rpy="0 0 0" xyz="0.49628 0 0"/>
    <parent link="r_hip_pitch_link"/>
    <child link="r_knee_pitch_link"/>
    <axis xyz="0 0 1"/>
    <limit effort="1000" lower="-1.570796327" upper="1.570796327" velocity="3"/>
    <dynamics damping="0.5" friction="8"/>
  </joint>
  <transmission name="r_knee_pitch_joint_tran">
    <type>transmission_interface/SimpleTransmission</type>
    <joint name="r_knee_pitch_joint">
      <hardwareInterface>hardware_interface/EffortJointInterface</hardwareInterface>
    </joint>
    <actuator name="r_knee_pitch_joint_motor">
      <hardwareInterface>EffortJointInterface</hardwareInterface>
      <mechanicalReduction>1</mechanicalReduction>
    </actuator>
  </transmission>
  <!-- right knee pitch link -->
  <link name="r_knee_pitch_link">
    <visual>
      <origin rpy="0 0 0" xyz="0 0 0"/>
      <geometry>
        <mesh filename="package://huron_description/meshes/r_knee_pitch_link.STL" scale="1 1 1"/>
      </geometry>
      <material name="grey"/>
    </visual>
    <collision>
      <origin rpy="0 0 0" xyz="0 0 0"/>
      <geometry>
        <mesh filename="package://huron_description/meshes/r_knee_pitch_link.STL" scale="1 1 1"/>
      </geometry>
      <material name="grey"/>
    </collision>
    <inertial>
      <origin rpy="0 0 0" xyz="0.13396 0.0006585 -0.0028723"/>
      <mass value="3.4875"/>
      <inertia ixx="0.0064812" ixy="1.2949E-05" ixz="2.8064E-05" iyy="0.019762" iyz="-1.0389E-05" izz="0.017354"/>
    </inertial>
  </link>
  <!-- right ankle pitch joint -->
  <joint name="r_ankle_pitch_joint" type="revolute">
    <origin rpy="0 0 0.0" xyz="0.37 0 0"/>
    <parent link="r_knee_pitch_link"/>
    <child link="r_ankle_pitch_link"/>
    <axis xyz="0 0 1"/>
    <limit effort="1000" lower="-0.5236" upper="0.1745" velocity="3"/>
    <dynamics damping="0.5" friction="4"/>
  </joint>
  <transmission name="r_ankle_pitch_joint_tran">
    <type>transmission_interface/SimpleTransmission</type>
    <joint name="r_ankle_pitch_joint">
      <hardwareInterface>hardware_interface/EffortJointInterface</hardwareInterface>
    </joint>
    <actuator name="r_ankle_pitch_joint_motor">
      <hardwareInterface>EffortJointInterface</hardwareInterface>
      <mechanicalReduction>1</mechanicalReduction>
    </actuator>
  </transmission>
  <!-- right ankle pitch link -->
  <link name="r_ankle_pitch_link">
    <visual>
      <origin rpy="0 0 0" xyz="0 0 0"/>
      <geometry>
        <mesh filename="package://huron_description/meshes/r_ankle_pitch_link.STL" scale="1 1 1"/>
      </geometry>
      <material name="">
        <color rgba="0.77647 0.75686 0.73725 1"/>
      </material>
    </visual>
    <collision>
      <origin rpy="0 0 0" xyz="0 0 0"/>
      <geometry>
        <mesh filename="package://huron_description/meshes/r_ankle_pitch_link.STL" scale="1 1 1"/>
      </geometry>
      <material name="">
        <color rgba="0.77647 0.75686 0.73725 1"/>
      </material>
    </collision>
    <inertial>
      <origin rpy="0 0 0" xyz="-0.029867 0.001045 0.000556"/>
      <mass value="2.4242"/>
      <inertia ixx="0.0025143" ixy="-0.00025651" ixz="1.5318E-12" iyy="0.0045125" iyz="9.9589E-10" izz="0.0049235"/>
    </inertial>
  </link>
  <!-- right ankle roll joint -->
  <joint name="r_ankle_roll_joint" type="revolute">
    <origin rpy="1.570796327 0 0" xyz="0 0 0"/>
    <parent link="r_ankle_pitch_link"/>
    <child link="r_ankle_roll_link"/>
    <axis xyz="0 0 1"/>
    <limit effort="1000" lower="-0.3491" upper="0.3491" velocity="3"/>
    <dynamics damping="0.5" friction="4"/>
  </joint>
  <transmission name="r_ankle_roll_joint_tran">
    <type>transmission_interface/SimpleTransmission</type>
    <joint name="r_ankle_roll_joint">
      <hardwareInterface>hardware_interface/EffortJointInterface</hardwareInterface>
    </joint>
    <actuator name="r_ankle_roll_joint_motor">
      <hardwareInterface>EffortJointInterface</hardwareInterface>
      <mechanicalReduction>1</mechanicalReduction>
    </actuator>
  </transmission>
  <!-- right ankle roll link -->
  <link name="r_ankle_roll_link">
    <visual>
      <origin rpy="0 0 0" xyz="0 0 0"/>
      <geometry>
        <mesh filename="package://huron_description/meshes/r_ankle_roll_link.STL" scale="1 1 1"/>
      </geometry>
      <material name="">
        <color rgba="0.77647 0.75686 0.73725 1"/>
      </material>
    </visual>
    <collision>
      <origin rpy="0 0 0" xyz="0 0 0"/>
      <geometry>
        <mesh filename="package://huron_description/meshes/r_ankle_roll_link.STL" scale="1 1 1"/>
      </geometry>
      <material name="">
        <color rgba="0.77647 0.75686 0.73725 1"/>
      </material>
    </collision>
    <inertial>
      <origin rpy="0 0 0" xyz="0.07353 -7.0757E-05 0.063933"/>
      <mass value="1.8633"/>
      <inertia ixx="0.0086817" ixy="9.8525E-06" ixz="0.00024324" iyy="0.0084053" iyz="-0.00012345" izz="0.0013019"/>
    </inertial>
  </link>
  <!-- right ft fixed joint 1 -->
  <joint name="r1_ft_fixed" type="revolute">
    <origin rpy="0 0 1.570796327" xyz="0.098297 0.01417 0.12788"/>
    <axis xyz="0 0 1"/>
    <parent link="r_ankle_roll_link"/>
    <child link="r1_foot_ft_link"/>
    <limit effort="100" lower="0" upper="0" velocity="100"/>
  </joint>
  <!-- right foot ft link 1 -->
  <link name="r1_foot_ft_link">
    <visual>
      <origin rpy=" 0 0 0" xyz="0 0 0"/>
      <geometry>
        <mesh filename="package://huron_description/meshes/r1_foot_ft_link.STL" scale="1 1 1"/>
      </geometry>
      <material name="green"/>
    </visual>
    <collision>
      <origin rpy=" 0 0 0" xyz="0 0 0"/>
      <geometry>
        <mesh filename="package://huron_description/meshes/r1_foot_ft_link.STL" scale="1 1 1"/>
      </geometry>
      <material name="green"/>
    </collision>
    <inertial>
      <origin rpy="0 0 0" xyz="4.02455846426619E-16 0.00477126123234806 2.77555756156289E-16"/>
      <mass value="0.00610112058812607"/>
      <inertia ixx="3.17133668071686E-07" ixy="-4.44802942503628E-22" ixz="-5.13396248201841E-23" iyy="4.87731969834605E-07" iyz="6.29534110948095E-22" izz="3.17133668071686E-07"/>
    </inertial>
  </link>
  <!-- right ft fixed joint 2 -->
  <joint name="r2_ft_fixed" type="revolute">
    <origin rpy="0 0 1.570796327" xyz="0.098297 -0.02083 0.12788"/>
    <axis xyz="0 0 1"/>
    <parent link="r_ankle_roll_link"/>
    <child link="r2_foot_ft_link"/>
    <limit effort="100" lower="0" upper="0" velocity="100"/>
  </joint>
  <!-- right foot ft link 2 -->
  <link name="r2_foot_ft_link">
    <visual>
      <origin rpy=" 0 0 0" xyz="0 0 0"/>
      <geometry>
        <mesh filename="package://huron_description/meshes/r2_foot_ft_link.STL" scale="1 1 1"/>
      </geometry>
      <material name="green"/>
    </visual>
    <collision>
      <origin rpy=" 0 0 0" xyz="0 0 0"/>
      <geometry>
        <mesh filename="package://huron_description/meshes/r2_foot_ft_link.STL" scale="1 1 1"/>
      </geometry>
      <material name="green"/>
    </collision>
    <inertial>
      <origin rpy="0 0 0" xyz="2.45636844198316E-15 0.00477126123234772 -5.55111512312578E-17"/>
      <mass value="0.00610112058812607"/>
      <inertia ixx="3.17133668071686E-07" ixy="-4.50854564995024E-22" ixz="-3.37723169777971E-23" iyy="4.87731969834605E-07" iyz="6.62187087857084E-22" izz="3.17133668071686E-07"/>
    </inertial>
  </link>
  <!-- right ft fixed joint 3 -->
  <joint name="r3_ft_fixed" type="revolute">
    <origin rpy="0 0 1.570796327" xyz="0.098297 -0.017008 0"/>
    <axis xyz="0 0 1"/>
    <parent link="r_ankle_roll_link"/>
    <child link="r3_foot_ft_link"/>
    <limit effort="100" lower="0" upper="0" velocity="100"/>
  </joint>
  <!-- right foot ft link 3 -->
  <link name="r3_foot_ft_link">
    <visual>
      <origin rpy=" 0 0 0" xyz="0 0 0"/>
      <geometry>
        <mesh filename="package://huron_description/meshes/r3_foot_ft_link.STL" scale="1 1 1"/>
      </geometry>
      <material name="green"/>
    </visual>
    <collision>
      <origin rpy=" 0 0 0" xyz="0 0 0"/>
      <geometry>
        <mesh filename="package://huron_description/meshes/r3_foot_ft_link.STL" scale="1 1 1"/>
      </geometry>
      <material name="green"/>
    </collision>
    <inertial>
      <origin rpy="0 0 0" xyz="1.84574577843932E-15 0.00477126123234928 -1.11022302462516E-16"/>
      <mass value="0.00610112058812607"/>
      <inertia ixx="3.17133668071686E-07" ixy="-4.50482113604524E-22" ixz="-5.92683031466877E-23" iyy="4.87731969834605E-07" iyz="6.6444452379759E-22" izz="3.17133668071686E-07"/>
    </inertial>
  </link>
  <!-- right ft fixed joint 4 -->
  <joint name="r4_ft_fixed" type="revolute">
    <origin rpy="0 0 1.570796327" xyz="0.098297 0.0165 0"/>
    <axis xyz="0 0 1"/>
    <parent link="r_ankle_roll_link"/>
    <child link="r4_foot_ft_link"/>
    <limit effort="100" lower="0" upper="0" velocity="100"/>
  </joint>
  <!-- right4 foot ft link 4 -->
  <link name="r4_foot_ft_link">
    <visual>
      <origin rpy=" 0 0 0" xyz="0 0 0"/>
      <geometry>
        <mesh filename="package://huron_description/meshes/r4_foot_ft_link.STL" scale="1 1 1"/>
      </geometry>
      <material name="green"/>
    </visual>
    <collision>
      <origin rpy=" 0 0 0" xyz="0 0 0"/>
      <geometry>
        <mesh filename="package://huron_description/meshes/r4_foot_ft_link.STL" scale="1 1 1"/>
      </geometry>
      <material name="green"/>
    </collision>
    <inertial>
      <origin rpy="0 0 0" xyz="1.80411241501588E-15 0.00477126123234772 -1.66533453693773E-16"/>
      <mass value="0.00610112058812607"/>
      <inertia ixx="3.17133668071686E-07" ixy="-4.47159964907589E-22" ixz="1.84653258585498E-23" iyy="4.87731969834605E-07" iyz="6.53995762781336E-22" izz="3.17133668071686E-07"/>
    </inertial>
  </link>
  <!-- right ft fixed joint -->
  <joint name="rv_ft_fixed" type="fixed">
    <origin rpy="0 0 0" xyz="0.0 0.0 0.0"/>
    <axis xyz="0 0 0"/>
    <parent link="r4_foot_ft_link"/>
    <child link="r_foot_v_ft_link"/>
    <limit effort="100" lower="0" upper="0" velocity="100"/>
  </joint>
  <!-- right foot ft link -->
  <link name="r_foot_v_ft_link"/>
  <!-- left hip yaw joint -->
  <joint name="l_hip_yaw_joint" type="revolute">
    <origin rpy="0 0 0" xyz="-0.0775000000000011 0 -0.1451242"/>
    <parent link="base_footprint"/>
    <child link="l_hip_yaw_link"/>
    <axis xyz="0 0 1"/>
    <limit effort="1000" lower="-3.1416" upper="3.1416" velocity="3"/>
    <dynamics damping="0.5" friction="8"/>
  </joint>
  <transmission name="l_hip_yaw_joint_tran">
    <type>transmission_interface/SimpleTransmission</type>
    <joint name="l_hip_yaw_joint">
      <hardwareInterface>hardware_interface/EffortJointInterface</hardwareInterface>
    </joint>
    <actuator name="l_hip_yaw_joint_motor">
      <hardwareInterface>EffortJointInterface</hardwareInterface>
      <mechanicalReduction>1</mechanicalReduction>
    </actuator>
  </transmission>
  <!-- left hip yaw link -->
  <link name="l_hip_yaw_link">
    <visual>
      <origin rpy="0 0 0" xyz="0 0 0"/>
      <geometry>
        <mesh filename="package://huron_description/meshes/l_hip_yaw_link.STL" scale="1 1 1"/>
      </geometry>
      <material name="grey"/>
    </visual>
    <collision>
      <origin rpy="0 0 0" xyz="0 0 0"/>
      <geometry>
        <mesh filename="package://huron_description/meshes/l_hip_yaw_link.STL" scale="1 1 1"/>
      </geometry>
      <material name="grey"/>
    </collision>
    <inertial>
      <origin rpy="0 0 0" xyz="0.00063365 -0.00053469 0.063496"/>
      <mass value="1.6968"/>
      <inertia ixx="0.0022702" ixy="-2.4951E-10" ixz="6.6464E-06" iyy="0.0026746" iyz="-5.1468E-09" izz="0.001238"/>
    </inertial>
  </link>
  <!-- left hip roll joint-->
  <joint name="l_hip_roll_joint" type="revolute">
    <origin rpy="1.570796327 0 3.141592654" xyz="0 0 0"/>
    <parent link="l_hip_yaw_link"/>
    <child link="l_hip_roll_link"/>
    <axis xyz="0 0 1"/>
    <limit effort="1000" lower="-0.01" upper="0.5236" velocity="3"/>
    <dynamics damping="0.5" friction="8"/>
  </joint>
  <transmission name="l_hip_roll_joint_tran">
    <type>transmission_interface/SimpleTransmission</type>
    <joint name="l_hip_roll_joint">
      <hardwareInterface>hardware_interface/EffortJointInterface</hardwareInterface>
    </joint>
    <actuator name="l_hip_roll_joint_motor">
      <hardwareInterface>EffortJointInterface</hardwareInterface>
      <mechanicalReduction>1</mechanicalReduction>
    </actuator>
  </transmission>
  <!-- left hip roll link -->
  <link name="l_hip_roll_link">
    <visual>
      <origin rpy="0 0 0" xyz="0 0 0"/>
      <geometry>
        <mesh filename="package://huron_description/meshes/l_hip_roll_link.STL" scale="1 1 1"/>
      </geometry>
      <material name="grey"/>
    </visual>
    <collision>
      <origin rpy="0 0 0" xyz="0 0 0"/>
      <geometry>
        <mesh filename="package://huron_description/meshes/l_hip_roll_link.STL" scale="1 1 1"/>
      </geometry>
      <material name="grey"/>
    </collision>
    <inertial>
      <origin rpy="0 0 0" xyz="0.07196 0.0061153 -0.0005211"/>
      <mass value="1.1884"/>
      <inertia ixx="0.00098222" ixy="-9.9267E-08" ixz="4.9764E-09" iyy="0.00097045" iyz="-9.7285E-08" izz="0.00092365"/>
    </inertial>
  </link>
  <!-- left hip pitch joint -->
  <joint name="l_hip_pitch_joint" type="revolute">
    <origin rpy="-1.570796327 0 -1.570796327" xyz="1.6665E-05 -0.0165 -5E-05"/>
    <parent link="l_hip_roll_link"/>
    <child link="l_hip_pitch_link"/>
    <axis xyz="0 0 1"/>
    <limit effort="1000" lower="-1.2217" upper="1.2217" velocity="3"/>
    <dynamics damping="0.5" friction="8"/>
  </joint>
  <transmission name="l_hip_pitch_joint_tran">
    <type>transmission_interface/SimpleTransmission</type>
    <joint name="l_hip_pitch_joint">
      <hardwareInterface>hardware_interface/EffortJointInterface</hardwareInterface>
    </joint>
    <actuator name="l_hip_pitch_joint_motor">
      <hardwareInterface>EffortJointInterface</hardwareInterface>
      <mechanicalReduction>1</mechanicalReduction>
    </actuator>
  </transmission>
  <!-- left hip pitch link -->
  <link name="l_hip_pitch_link">
    <visual>
      <origin rpy="0 0 0" xyz="0 0 0"/>
      <geometry>
        <mesh filename="package://huron_description/meshes/l_hip_pitch_link.STL" scale="1 1 1"/>
      </geometry>
      <material name="grey"/>
    </visual>
    <collision>
      <origin rpy="0 0 0" xyz="0 0 0"/>
      <geometry>
        <mesh filename="package://huron_description/meshes/l_hip_pitch_link.STL" scale="1 1 1"/>
      </geometry>
      <material name="grey"/>
    </collision>
    <inertial>
      <origin rpy="0 0 0" xyz="0.25103 -7.7295E-06 0.053135"/>
      <mass value="4.2544"/>
      <inertia ixx="0.0034501" ixy="-1.1102E-07" ixz="0.0019797" iyy="0.010035" iyz="-4.8767E-10" izz="0.01009"/>
    </inertial>
  </link>
  <!-- left knee pitch joint -->
  <joint name="l_knee_pitch_joint" type="revolute">
    <origin rpy="0 0 0" xyz="0.49628 0 0"/>
    <parent link="l_hip_pitch_link"/>
    <child link="l_knee_pitch_link"/>
    <axis xyz="0 0 1"/>
    <limit effort="1000" lower="-1.570796327" upper="1.570796327" velocity="3"/>
    <dynamics damping="0.5" friction="8"/>
  </joint>
  <transmission name="l_knee_pitch_joint_tran">
    <type>transmission_interface/SimpleTransmission</type>
    <joint name="l_knee_pitch_joint">
      <hardwareInterface>hardware_interface/EffortJointInterface</hardwareInterface>
    </joint>
    <actuator name="l_knee_pitch_joint_motor">
      <hardwareInterface>EffortJointInterface</hardwareInterface>
      <mechanicalReduction>1</mechanicalReduction>
    </actuator>
  </transmission>
  <!-- left knee pitch link -->
  <link name="l_knee_pitch_link">
    <visual>
      <origin rpy="0 0 0" xyz="0 0 0"/>
      <geometry>
        <mesh filename="package://huron_description/meshes/l_knee_pitch_link.STL" scale="1 1 1"/>
      </geometry>
      <material name="grey"/>
    </visual>
    <collision>
      <origin rpy="0 0 0" xyz="0 0 0"/>
      <geometry>
        <mesh filename="package://huron_description/meshes/l_knee_pitch_link.STL" scale="1 1 1"/>
      </geometry>
      <material name="grey"/>
    </collision>
    <inertial>
      <origin rpy="0 0 0" xyz="0.13397 0.00066001 0.0028723"/>
      <mass value="3.4875"/>
      <inertia ixx="0.0064814" ixy="1.2524E-05" ixz="-2.7966E-05" iyy="0.019762" iyz="1.0417E-05" izz="0.017354"/>
    </inertial>
  </link>
  <!-- left ankle pitch joint -->
  <joint name="l_ankle_pitch_joint" type="revolute">
    <origin rpy="0 0 0.0" xyz="0.37 0 0"/>
    <parent link="l_knee_pitch_link"/>
    <child link="l_ankle_pitch_link"/>
    <axis xyz="0 0 1"/>
    <limit effort="1000" lower="-0.5236" upper="0.1745" velocity="3"/>
    <dynamics damping="0.5" friction="4"/>
  </joint>
  <transmission name="l_ankle_pitch_joint_tran">
    <type>transmission_interface/SimpleTransmission</type>
    <joint name="l_ankle_pitch_joint">
      <hardwareInterface>hardware_interface/EffortJointInterface</hardwareInterface>
    </joint>
    <actuator name="l_ankle_pitch_joint_motor">
      <hardwareInterface>EffortJointInterface</hardwareInterface>
      <mechanicalReduction>1</mechanicalReduction>
    </actuator>
  </transmission>
  <!-- left ankle pitch link -->
  <link name="l_ankle_pitch_link">
    <visual>
      <origin rpy="0 0 0" xyz="0 0 0"/>
      <geometry>
        <mesh filename="package://huron_description/meshes/l_ankle_pitch_link.STL" scale="1 1 1"/>
      </geometry>
      <material name="">
        <color rgba="0.89804 0.91765 0.92941 1"/>
      </material>
    </visual>
    <collision>
      <origin rpy="0 0 0" xyz="0 0 0"/>
      <geometry>
        <mesh filename="package://huron_description/meshes/l_ankle_pitch_link.STL" scale="1 1 1"/>
      </geometry>
      <material name="">
        <color rgba="0.89804 0.91765 0.92941 1"/>
      </material>
    </collision>
    <inertial>
      <origin rpy="0 0 0" xyz="-0.029808 0.001045 3.1134E-08"/>
      <mass value="2.4242"/>
      <inertia ixx="0.0025143" ixy="-0.00025651" ixz="1.1633E-12" iyy="0.0045125" iyz="6.7197E-10" izz="0.0049235"/>
    </inertial>
  </link>
  <!-- left ankle roll pitch -->
  <joint name="l_ankle_roll_joint" type="revolute">
    <origin rpy="1.570796327 0 0" xyz="0 0 0"/>
    <parent link="l_ankle_pitch_link"/>
    <child link="l_ankle_roll_link"/>
    <axis xyz="0 0 1"/>
    <limit effort="1000" lower="-0.3491" upper="0.3491" velocity="3"/>
    <dynamics damping="0.5" friction="4"/>
  </joint>
  <transmission name="l_ankle_roll_joint_tran">
    <type>transmission_interface/SimpleTransmission</type>
    <joint name="l_ankle_roll_joint">
      <hardwareInterface>hardware_interface/EffortJointInterface</hardwareInterface>
    </joint>
    <actuator name="l_ankle_roll_joint_motor">
      <hardwareInterface>EffortJointInterface</hardwareInterface>
      <mechanicalReduction>1</mechanicalReduction>
    </actuator>
  </transmission>
  <!-- left ankle roll link -->
  <link name="l_ankle_roll_link">
    <visual>
      <origin rpy="0 0 0" xyz="0 0 0"/>
      <geometry>
        <mesh filename="package://huron_description/meshes/l_ankle_roll_link.STL" scale="1 1 1"/>
      </geometry>
      <material name="">
        <color rgba="0.77647 0.75686 0.73725 1"/>
      </material>
    </visual>
    <collision>
      <origin rpy="0 0 0" xyz="0 0 0"/>
      <geometry>
        <mesh filename="package://huron_description/meshes/l_ankle_roll_link.STL" scale="1 1 1"/>
      </geometry>
      <material name="">
        <color rgba="0.77647 0.75686 0.73725 1"/>
      </material>
    </collision>
    <inertial>
      <origin rpy="0 0 0" xyz="0.07353 6.708E-05 0.063947"/>
      <mass value="1.8633"/>
      <inertia ixx="0.0086824" ixy="-9.8353E-06" ixz="0.00024334" iyy="0.0084059" iyz="0.00012379" izz="0.0013021"/>
    </inertial>
  </link>
  <!-- left ft fixed joint 1 -->
  <joint name="l1_ft_fixed" type="revolute">
    <origin rpy="0 0 1.570796327" xyz="0.098297 0.02083 0.12788"/>
    <axis xyz="0 0 1"/>
    <parent link="l_ankle_roll_link"/>
    <child link="l1_foot_ft_link"/>
    <limit effort="100" lower="0" upper="0" velocity="100"/>
  </joint>
  <!-- left foot ft link 1 -->
  <link name="l1_foot_ft_link">
    <visual>
      <origin rpy=" 0 0 0" xyz="0 0 0"/>
      <geometry>
        <mesh filename="package://huron_description/meshes/l1_foot_ft_link.STL" scale="1 1 1"/>
      </geometry>
      <material name="green"/>
    </visual>
    <collision>
      <origin rpy=" 0 0 0" xyz="0 0 0"/>
      <geometry>
        <mesh filename="package://huron_description/meshes/l1_foot_ft_link.STL" scale="1 1 1"/>
      </geometry>
      <material name="green"/>
    </collision>
    <inertial>
      <origin rpy="0 0 0" xyz="-5.7176E-15 0.0047713 3.2752E-15"/>
      <mass value="0.0061011"/>
      <inertia ixx="3.1713E-07" ixy="3.8307E-22" ixz="-1.1921E-22" iyy="4.8773E-07" iyz="-1.0683E-22" izz="3.1713E-07"/>
    </inertial>
  </link>
  <!-- left ft fixed joint 2 -->
  <joint name="l2_ft_fixed" type="revolute">
    <origin rpy="0 0 1.570796327" xyz="0.098297 -0.01417 0.12788"/>
    <axis xyz="0 0 1"/>
    <parent link="l_ankle_roll_link"/>
    <child link="l2_foot_ft_link"/>
    <limit effort="100" lower="0" upper="0" velocity="100"/>
  </joint>
  <!-- left foot ft link 2 -->
  <link name="l2_foot_ft_link">
    <visual>
      <origin rpy=" 0 0 0" xyz="0 0 0"/>
      <geometry>
        <mesh filename="package://huron_description/meshes/l2_foot_ft_link.STL" scale="1 1 1"/>
      </geometry>
      <material name="green"/>
    </visual>
    <collision>
      <origin rpy=" 0 0 0" xyz="0 0 0"/>
      <geometry>
        <mesh filename="package://huron_description/meshes/l2_foot_ft_link.STL" scale="1 1 1"/>
      </geometry>
      <material name="green"/>
    </collision>
    <inertial>
      <origin rpy="0 0 0" xyz="-4.46864767411626E-15 0.00477126123234917 2.4980018054066E-15"/>
      <mass value="0.00610112058812606"/>
      <inertia ixx="3.17133668071686E-07" ixy="4.81665130591134E-22" ixz="-8.8406170379935E-23" iyy="4.87731969834605E-07" iyz="-8.74913874421171E-23" izz="3.17133668071686E-07"/>
    </inertial>
  </link>
  <!-- left ft fixed joint 3 -->
  <joint name="l3_ft_fixed" type="revolute">
    <origin rpy="0 0 1.570796327" xyz="0.098297 -0.0165 0"/>
    <axis xyz="0 0 1"/>
    <parent link="l_ankle_roll_link"/>
    <child link="l3_foot_ft_link"/>
    <limit effort="100" lower="0" upper="0" velocity="100"/>
  </joint>
  <!-- left foot ft link 3 -->
  <link name="l3_foot_ft_link">
    <visual>
      <origin rpy=" 0 0 0" xyz="0 0 0"/>
      <geometry>
        <mesh filename="package://huron_description/meshes/l3_foot_ft_link.STL" scale="1 1 1"/>
      </geometry>
      <material name="green"/>
    </visual>
    <collision>
      <origin rpy=" 0 0 0" xyz="0 0 0"/>
      <geometry>
        <mesh filename="package://huron_description/meshes/l3_foot_ft_link.STL" scale="1 1 1"/>
      </geometry>
      <material name="green"/>
    </collision>
    <inertial>
      <origin rpy="0 0 0" xyz="-2.19269047363468E-15 0.00477126123234894 1.4432899320127E-15"/>
      <mass value="0.00610112058812606"/>
      <inertia ixx="3.17133668071686E-07" ixy="4.98475719906322E-22" ixz="-6.41076334805219E-23" iyy="4.87731969834605E-07" iyz="-7.83706170725903E-23" izz="3.17133668071686E-07"/>
    </inertial>
  </link>
  <!-- left ft fixed joint 4 -->
  <joint name="l4_ft_fixed" type="revolute">
    <origin rpy="0 0 1.570796327" xyz="0.098297 0.017008 0"/>
    <axis xyz="0 0 1"/>
    <parent link="l_ankle_roll_link"/>
    <child link="l4_foot_ft_link"/>
    <limit effort="100" lower="0" upper="0" velocity="100"/>
  </joint>
  <!-- left foot ft link 4 -->
  <link name="l4_foot_ft_link">
    <visual>
      <origin rpy=" 0 0 0" xyz="0 0 0"/>
      <geometry>
        <mesh filename="package://huron_description/meshes/l4_foot_ft_link.STL" scale="1 1 1"/>
      </geometry>
      <material name="green"/>
    </visual>
    <collision>
      <origin rpy=" 0 0 0" xyz="0 0 0"/>
      <geometry>
        <mesh filename="package://huron_description/meshes/l4_foot_ft_link.STL" scale="1 1 1"/>
      </geometry>
      <material name="green"/>
    </collision>
    <inertial>
      <origin rpy="0 0 0" xyz="-8.32667268468867E-16 0.00477126123234917 6.66133814775094E-16"/>
      <mass value="0.00610112058812606"/>
      <inertia ixx="3.17133668071686E-07" ixy="3.66436341457745E-22" ixz="5.6860083747849E-23" iyy="4.87731969834605E-07" iyz="-1.13521885241387E-22" izz="3.17133668071686E-07"/>
    </inertial>
  </link>
  <!-- left ft fixed joint -->
  <joint name="lv_ft_fixed" type="fixed">
    <origin rpy="0 -1.570796327 0" xyz="0.045 0.0 0.0"/>
    <parent link="l4_foot_ft_link"/>
    <child link="l_foot_v_ft_link"/>
  </joint>
  <!-- left foot ft link -->
  <link name="l_foot_v_ft_link"/>
</robot>

