<?xml version="1.0" ?>
<!-- =================================================================================== -->
<!-- |    This document was autogenerated by xacro from huron.xacro                    | -->
<!-- |    EDITING THIS FILE BY HAND IS NOT RECOMMENDED                                 | -->
<!-- =================================================================================== -->
<robot name="huron">
  <material name="black">
    <color rgba="0.0 0.0 0.0 1.0"/>
  </material>
  <material name="blue">
    <color rgba="0.0 0.0 0.8 1.0"/>
  </material>
  <material name="green">
    <color rgba="0.0 0.8 0.0 1.0"/>
  </material>
  <material name="grey">
    <color rgba="0.75294 0.75294 0.75294 1"/>
  </material>
  <material name="orange">
    <color rgba="1.0 0.4235294117647059 0.0392156862745098 1.0"/>
  </material>
  <material name="brown">
    <color rgba="0.8705882352941177 0.8117647058823529 0.7647058823529411 1.0"/>
  </material>
  <material name="red">
    <color rgba="0.8 0.0 0.0 1.0"/>
  </material>
  <material name="white">
    <color rgba="1.0 1.0 1.0 1.0"/>
  </material>
  <!-- Right leg -->
  <!-- Right foot sensors -->
  <!-- ros_control plugin -->
  <gazebo>
    <plugin filename="libgazebo_ros_control.so" name="gazebo_ros_control">
      <robotNamespace>/huron</robotNamespace>
    </plugin>
  </gazebo>
  <gazebo>
    <plugin filename="libgazebo_ros_p3d.so" name="ground_truth">
      <frameName>map</frameName>
      <bodyName>base_link</bodyName>
      <topicName>/huron/odom</topicName>
      <updateRate>100.0</updateRate>
    </plugin>
  </gazebo>
  <!-- imu sensor -->
  <gazebo reference="imu_link">
    <gravity>true</gravity>
    <sensor name="imu_sensor" type="imu">
      <always_on>true</always_on>
      <update_rate>100</update_rate>
      <visualize>true</visualize>
      <topic>/huron/sensor/imu</topic>
      <plugin filename="libgazebo_ros_imu_sensor.so" name="imu_plugin">
        <topicName>huron/sensor/imu</topicName>
        <bodyName>imu_link</bodyName>
        <updateRateHZ>10.0</updateRateHZ>
        <gaussianNoise>0.0</gaussianNoise>
        <xyzOffset>0 0 0</xyzOffset>
        <rpyOffset>0 0 0</rpyOffset>
        <frameName>imu_link</frameName>
      </plugin>
      <pose>0 0 0 0 0 0</pose>
    </sensor>
  </gazebo>
  <gazebo reference="r1_ft_fixed">
    <provideFeedback>true</provideFeedback>
  </gazebo>
  <gazebo>
    <plugin filename="libgazebo_ros_ft_sensor.so" name="r1_ft_sensor">
      <updateRate>100.0</updateRate>
      <topicName>/huron/sensor/r1_ft_sensor</topicName>
      <jointName>r1_ft_fixed</jointName>
      <gaussianNoise>0.0</gaussianNoise>
    </plugin>
  </gazebo>
  <gazebo reference="r2_ft_fixed">
    <provideFeedback>true</provideFeedback>
  </gazebo>
  <gazebo>
    <plugin filename="libgazebo_ros_ft_sensor.so" name="r2_ft_sensor">
      <updateRate>100.0</updateRate>
      <topicName>/huron/sensor/r2_ft_sensor</topicName>
      <jointName>r2_ft_fixed</jointName>
      <gaussianNoise>0.0</gaussianNoise>
    </plugin>
  </gazebo>
  <gazebo reference="r3_ft_fixed">
    <provideFeedback>true</provideFeedback>
  </gazebo>
  <gazebo>
    <plugin filename="libgazebo_ros_ft_sensor.so" name="r3_ft_sensor">
      <updateRate>100.0</updateRate>
      <topicName>/huron/sensor/r3_ft_sensor</topicName>
      <jointName>r3_ft_fixed</jointName>
      <gaussianNoise>0.0</gaussianNoise>
    </plugin>
  </gazebo>
  <gazebo reference="r4_ft_fixed">
    <provideFeedback>true</provideFeedback>
  </gazebo>
  <gazebo>
    <plugin filename="libgazebo_ros_ft_sensor.so" name="r4_ft_sensor">
      <updateRate>100.0</updateRate>
      <topicName>/huron/sensor/r4_ft_sensor</topicName>
      <jointName>r4_ft_fixed</jointName>
      <gaussianNoise>0.0</gaussianNoise>
    </plugin>
  </gazebo>
  <gazebo reference="l1_ft_fixed">
    <provideFeedback>true</provideFeedback>
  </gazebo>
  <gazebo>
    <plugin filename="libgazebo_ros_ft_sensor.so" name="l1_ft_sensor">
      <updateRate>100.0</updateRate>
      <topicName>/huron/sensor/l1_ft_sensor</topicName>
      <jointName>l1_ft_fixed</jointName>
      <gaussianNoise>0.0</gaussianNoise>
    </plugin>
  </gazebo>
  <gazebo reference="l2_ft_fixed">
    <provideFeedback>true</provideFeedback>
  </gazebo>
  <gazebo>
    <plugin filename="libgazebo_ros_ft_sensor.so" name="l2_ft_sensor">
      <updateRate>100.0</updateRate>
      <topicName>/huron/sensor/l2_ft_sensor</topicName>
      <jointName>l2_ft_fixed</jointName>
      <gaussianNoise>0.0</gaussianNoise>
    </plugin>
  </gazebo>
  <gazebo reference="l3_ft_fixed">
    <provideFeedback>true</provideFeedback>
  </gazebo>
  <gazebo>
    <plugin filename="libgazebo_ros_ft_sensor.so" name="l3_ft_sensor">
      <updateRate>100.0</updateRate>
      <topicName>/huron/sensor/l3_ft_sensor</topicName>
      <jointName>l3_ft_fixed</jointName>
      <gaussianNoise>0.0</gaussianNoise>
    </plugin>
  </gazebo>
  <gazebo reference="l4_ft_fixed">
    <provideFeedback>true</provideFeedback>
  </gazebo>
  <gazebo>
    <plugin filename="libgazebo_ros_ft_sensor.so" name="r4_ft_sensor">
      <updateRate>100.0</updateRate>
      <topicName>/huron/sensor/l4_ft_sensor</topicName>
      <jointName>l4_ft_fixed</jointName>
      <gaussianNoise>0.0</gaussianNoise>
    </plugin>
  </gazebo>
  <!-- World -->
  <gazebo reference="world"/>
  <!-- Map -->
  <gazebo reference="map"/>
  <!-- Base -->
  <gazebo reference="base_link"/>
  <!-- IMU -->
  <gazebo reference="imu_link"/>
  <!-- Body-->
  <gazebo reference="base_footprint">
    <mu1>0.2</mu1>
    <mu2>0.2</mu2>
    <material>Gazebo/Grey</material>
    <selfCollide>true</selfCollide>
  </gazebo>
  <!-- Battery -->
  <gazebo reference="battery_link">
    <material>Gazebo/SkyBlue</material>
    <selfCollide>true</selfCollide>
  </gazebo>
  <!-- Left Leg -->
  <gazebo reference="l_hip_yaw_link">
    <mu1>0.2</mu1>
    <mu2>0.2</mu2>
    <material>Gazebo/Grey</material>
    <selfCollide>true</selfCollide>
  </gazebo>
  <gazebo reference="l_hip_roll_link">
    <mu1>0.2</mu1>
    <mu2>0.2</mu2>
    <material>Gazebo/Grey</material>
    <selfCollide>true</selfCollide>
  </gazebo>
  <gazebo reference="l_hip_pitch_link">
    <mu1>0.2</mu1>
    <mu2>0.2</mu2>
    <material>Gazebo/Grey</material>
    <selfCollide>true</selfCollide>
  </gazebo>
  <gazebo reference="l_knee_pitch_link">
    <mu1>0.2</mu1>
    <mu2>0.2</mu2>
    <material>Gazebo/Grey</material>
    <selfCollide>true</selfCollide>
  </gazebo>
  <gazebo reference="l_ankle_pitch_link">
    <mu1>0.2</mu1>
    <mu2>0.2</mu2>
    <material>Gazebo/Grey</material>
    <selfCollide>true</selfCollide>
  </gazebo>
  <gazebo reference="l_ankle_roll_link">
    <kp>100000.0</kp>
    <kd>100.0</kd>
    <mu1>0.9</mu1>
    <mu2>0.9</mu2>
    <!--<maxContacts>30</maxContacts>-->
    <fdir1>1 0 0</fdir1>
    <maxVel>1.0</maxVel>
    <minDepth>0.001</minDepth>
    <material>Gazebo/Blue</material>
  </gazebo>
  <gazebo reference="l1_foot_ft_link">
    <kp>100000.0</kp>
    <kd>100.0</kd>
    <mu1>0.9</mu1>
    <mu2>0.9</mu2>
    <!--<maxContacts>30</maxContacts>-->
    <!-- <fdir1>1 0 0</fdir1> -->
    <maxVel>1.0</maxVel>
    <minDepth>0.0001</minDepth>
    <material>Gazebo/Orange</material>
  </gazebo>
  <gazebo reference="l2_foot_ft_link">
    <kp>100000.0</kp>
    <kd>100.0</kd>
    <mu1>0.9</mu1>
    <mu2>0.9</mu2>
    <!--<maxContacts>30</maxContacts>-->
    <!-- <fdir1>1 0 0</fdir1> -->
    <maxVel>1.0</maxVel>
    <minDepth>0.0001</minDepth>
    <material>Gazebo/Orange</material>
  </gazebo>
  <gazebo reference="l3_foot_ft_link">
    <kp>100000.0</kp>
    <kd>100.0</kd>
    <mu1>0.9</mu1>
    <mu2>0.9</mu2>
    <!--<maxContacts>30</maxContacts>-->
    <!-- <fdir1>1 0 0</fdir1> -->
    <maxVel>1.0</maxVel>
    <minDepth>0.0001</minDepth>
    <material>Gazebo/Orange</material>
  </gazebo>
  <gazebo reference="l4_foot_ft_link">
    <kp>100000.0</kp>
    <kd>100.0</kd>
    <mu1>0.9</mu1>
    <mu2>0.9</mu2>
    <!--<maxContacts>30</maxContacts>-->
    <!-- <fdir1>1 0 0</fdir1> -->
    <maxVel>1.0</maxVel>
    <minDepth>0.0001</minDepth>
    <material>Gazebo/Orange</material>
  </gazebo>
  <!-- Right Leg -->
  <gazebo reference="r_hip_yaw_link">
    <mu1>0.2</mu1>
    <mu2>0.2</mu2>
    <material>Gazebo/Grey</material>
    <selfCollide>true</selfCollide>
  </gazebo>
  <gazebo reference="r_hip_roll_link">
    <mu1>0.2</mu1>
    <mu2>0.2</mu2>
    <material>Gazebo/Grey</material>
    <selfCollide>true</selfCollide>
  </gazebo>
  <gazebo reference="r_hip_pitch_link">
    <mu1>0.2</mu1>
    <mu2>0.2</mu2>
    <material>Gazebo/Grey</material>
    <selfCollide>true</selfCollide>
  </gazebo>
  <gazebo reference="r_knee_pitch_link">
    <mu1>0.2</mu1>
    <mu2>0.2</mu2>
    <material>Gazebo/Grey</material>
    <selfCollide>true</selfCollide>
  </gazebo>
  <gazebo reference="r_ankle_pitch_link">
    <mu1>0.2</mu1>
    <mu2>0.2</mu2>
    <material>Gazebo/Grey</material>
    <selfCollide>true</selfCollide>
  </gazebo>
  <gazebo reference="r_ankle_roll_link">
    <kp>100000.0</kp>
    <kd>100.0</kd>
    <mu1>0.9</mu1>
    <mu2>0.9</mu2>
    <!--<maxContacts>30</maxContacts>-->
    <fdir1>1 0 0</fdir1>
    <maxVel>1.0</maxVel>
    <minDepth>0.0001</minDepth>
    <material>Gazebo/Blue</material>
  </gazebo>
  <gazebo reference="r1_foot_ft_link">
    <kp>100000.0</kp>
    <kd>100.0</kd>
    <mu1>0.9</mu1>
    <mu2>0.9</mu2>
    <!--<maxContacts>30</maxContacts>-->
    <!-- <fdir1>1 0 0</fdir1> -->
    <maxVel>1.0</maxVel>
    <minDepth>0.0001</minDepth>
    <material>Gazebo/Orange</material>
  </gazebo>
  <gazebo reference="r2_foot_ft_link">
    <kp>100000.0</kp>
    <kd>100.0</kd>
    <mu1>0.9</mu1>
    <mu2>0.9</mu2>
    <!--<maxContacts>30</maxContacts>-->
    <!-- <fdir1>1 0 0</fdir1> -->
    <maxVel>1.0</maxVel>
    <minDepth>0.0001</minDepth>
    <material>Gazebo/Orange</material>
  </gazebo>
  <gazebo reference="r3_foot_ft_link">
    <kp>100000.0</kp>
    <kd>100.0</kd>
    <mu1>0.9</mu1>
    <mu2>0.9</mu2>
    <!--<maxContacts>30</maxContacts>-->
    <!-- <fdir1>1 0 0</fdir1> -->
    <maxVel>1.0</maxVel>
    <minDepth>0.0001</minDepth>
    <material>Gazebo/Orange</material>
  </gazebo>
  <gazebo reference="r4_foot_ft_link">
    <kp>100000.0</kp>
    <kd>100.0</kd>
    <mu1>0.9</mu1>
    <mu2>0.9</mu2>
    <!--<maxContacts>30</maxContacts>-->
    <!-- <fdir1>1 0 0</fdir1> -->
    <maxVel>1.0</maxVel>
    <minDepth>0.0001</minDepth>
    <material>Gazebo/Orange</material>
  </gazebo>
  <!-- Used for fixing robot -->
  <!--<link name="world"></link> 
    <joint name="world_fixed" type="fixed">
        <origin xyz="0 0 0.764" rpy="0 0 0"/>
        <parent link="world"/>
        <child link="base_link"/>
    </joint> -->
  <link name="base_link"/>
  <joint name="base_fixed" type="fixed">
    <origin rpy="0 0 0" xyz="0 0 0"/>
    <parent link="base_link"/>
    <child link="base_footprint"/>
  </joint>
  <!-- base_link -->
  <link name="base_footprint">
    <visual>
      <origin rpy="0 0 0" xyz="0 0 0"/>
      <geometry>
        <mesh filename="package://huron_description/meshes/base_link.STL" scale="1 1 1"/>
      </geometry>
      <material name="grey"/>
    </visual>
    <collision>
      <origin rpy="0 0 0" xyz="0 0 0"/>
      <geometry>
        <mesh filename="package://huron_description/meshes/base_link.STL" scale="1 1 1"/>
      </geometry>
      <material name="grey"/>
    </collision>
    <inertial>
      <origin rpy="0 0 0" xyz="4.7319E-09 5.4338E-07 0.026975"/>
      <mass value="3.4072"/>
      <inertia ixx="0.00319" ixy="7.149E-11" ixz="6.0313E-11" iyy="0.010531" iyz="6.926E-09" izz="0.012315"/>
    </inertial>
  </link>
  <!-- Battery -->
  <link name="battery_link">
    <visual>
      <origin rpy="0 0 0" xyz="0 0 0"/>
      <geometry>
        <box size="0.065 0.188 0.151"/>
      </geometry>
      <material name="blue"/>
    </visual>
    <collision>
      <origin rpy="0 0 0" xyz="0 0 0"/>
      <geometry>
        <box size="0.065 0.188 0.151"/>
      </geometry>
      <material name="blue"/>
    </collision>
    <inertial>
      <origin rpy="0 0 0" xyz="0 0 0"/>
      <mass value="3.90089"/>
      <inertia ixx="0.01890143742" ixy="0" ixz="0" iyy="0.0128628597" iyz="0" izz="0.008785454428"/>
    </inertial>
  </link>
  <joint name="battery_fixed" type="fixed">
    <origin rpy="0 0 0" xyz="0 0 0.0895"/>
    <parent link="base_footprint"/>
    <child link="battery_link"/>
  </joint>
  <!-- imu joint -->
  <joint name="imu_fixed" type="fixed">
    <origin rpy="0 0 0" xyz="0 0 0"/>
    <parent link="base_footprint"/>
    <child link="imu_link"/>
  </joint>
  <link name="imu_link"/>
  <!-- right hip yaw joint -->
  <joint name="r_hip_yaw_joint" type="revolute">
    <origin rpy="0 0 3.141592654" xyz="0.0774999999999944 0 -0.1451242"/>
    <parent link="base_footprint"/>
    <child link="r_hip_yaw_link"/>
    <axis xyz="0 0 1"/>
    <limit effort="1000" lower="-3.1416" upper="3.1416" velocity="3"/>
    <dynamics damping="0.5" friction="5"/>
  </joint>
  <transmission name="r_hip_yaw_joint_tran">
    <type>transmission_interface/SimpleTransmission</type>
    <joint name="r_hip_yaw_joint">
      <hardwareInterface>hardware_interface/EffortJointInterface</hardwareInterface>
    </joint>
    <actuator name="r_hip_yaw_joint_motor">
      <hardwareInterface>EffortJointInterface</hardwareInterface>
      <mechanicalReduction>1</mechanicalReduction>
    </actuator>
  </transmission>
  <!-- right hip yaw link -->
  <link name="r_hip_yaw_link">
    <visual>
      <origin rpy="0 0 0" xyz="0 0 0"/>
      <geometry>
        <mesh filename="package://huron_description/meshes/r_hip_yaw_link.STL" scale="1 1 1"/>
      </geometry>
      <material name="grey"/>
    </visual>
    <collision>
      <origin rpy="0 0 0" xyz="0 0 0"/>
      <geometry>
        <mesh filename="package://huron_description/meshes/r_hip_yaw_link.STL" scale="1 1 1"/>
      </geometry>
      <material name="grey"/>
    </collision>
    <inertial>
      <origin rpy="0 0 0" xyz="0.0006244 0.00052023 0.063505"/>
      <mass value="1.6968"/>
      <inertia ixx="0.0022729" ixy="-5.6517E-10" ixz="6.6464E-06" iyy="0.0026746" iyz="5.6889E-09" izz="0.0012354"/>
    </inertial>
  </link>
  <!-- right hip roll joint-->
  <joint name="r_hip_roll_joint" type="revolute">
    <origin rpy="1.570796327 0 0" xyz="0 0 0"/>
    <parent link="r_hip_yaw_link"/>
    <child link="r_hip_roll_link"/>
    <axis xyz="0 0 1"/>
    <limit effort="1000" lower="-0.5236" upper="0.01" velocity="3"/>
    <dynamics damping="0.5" friction="5"/>
  </joint>
  <transmission name="r_hip_roll_joint_tran">
    <type>transmission_interface/SimpleTransmission</type>
    <joint name="r_hip_roll_joint">
      <hardwareInterface>hardware_interface/EffortJointInterface</hardwareInterface>
    </joint>
    <actuator name="r_hip_roll_joint_motor">
      <hardwareInterface>EffortJointInterface</hardwareInterface>
      <mechanicalReduction>1</mechanicalReduction>
    </actuator>
  </transmission>
  <!-- right hip roll link -->
  <link name="r_hip_roll_link">
    <visual>
      <origin rpy="0 0 0" xyz="0 0 0"/>
      <geometry>
        <mesh filename="package://huron_description/meshes/r_hip_roll_link.STL" scale="1 1 1"/>
      </geometry>
      <material name="grey"/>
    </visual>
    <collision>
      <origin rpy="0 0 0" xyz="0 0 0"/>
      <geometry>
        <mesh filename="package://huron_description/meshes/r_hip_roll_link.STL" scale="1 1 1"/>
      </geometry>
      <material name="grey"/>
    </collision>
    <inertial>
      <origin rpy="0 0 0" xyz="-0.07196 0.0061152 -0.00052563"/>
      <mass value="1.1884"/>
      <inertia ixx="0.00098222" ixy="9.8947E-08" ixz="9.2484E-09" iyy="0.00097045" iyz="9.7414E-08" izz="0.00092365"/>
    </inertial>
  </link>
  <!-- right hip pitch joint -->
  <joint name="r_hip_pitch_joint" type="revolute">
    <origin rpy="-1.570796327 0 -1.570796327" xyz="0 0 0"/>
    <parent link="r_hip_roll_link"/>
    <child link="r_hip_pitch_link"/>
    <axis xyz="0 0 1"/>
    <limit effort="1000" lower="-1.2217" upper="1.2217" velocity="3"/>
    <dynamics damping="0.5" friction="5"/>
  </joint>
  <transmission name="r_hip_pitch_joint_tran">
    <type>transmission_interface/SimpleTransmission</type>
    <joint name="r_hip_pitch_joint">
      <hardwareInterface>hardware_interface/EffortJointInterface</hardwareInterface>
    </joint>
    <actuator name="r_hip_pitch_joint_motor">
      <hardwareInterface>EffortJointInterface</hardwareInterface>
      <mechanicalReduction>1</mechanicalReduction>
    </actuator>
  </transmission>
  <!-- right hip pitch link -->
  <link name="r_hip_pitch_link">
    <visual>
      <origin rpy="0 0 0" xyz="0 0 0"/>
      <geometry>
        <mesh filename="package://huron_description/meshes/r_hip_pitch_link.STL" scale="1 1 1"/>
      </geometry>
      <material name="grey"/>
    </visual>
    <collision>
      <origin rpy="0 0 0" xyz="0 0 0"/>
      <geometry>
        <mesh filename="package://huron_description/meshes/r_hip_pitch_link.STL" scale="1 1 1"/>
      </geometry>
      <material name="grey"/>
    </collision>
    <inertial>
      <origin rpy="0 0 0" xyz="0.26753 4.9957E-05 -0.053132"/>
      <mass value="4.2544"/>
      <inertia ixx="0.0034501" ixy="-2.7593E-09" ixz="-0.0019797" iyy="0.010035" iyz="2.5351E-10" izz="0.01009"/>
    </inertial>
  </link>
  <!-- right knee pitch joint -->
  <joint name="r_knee_pitch_joint" type="revolute">
    <origin rpy="0 0 0" xyz="0.512778478308813 4.99999999867273E-05 -1.66647320091612E-05"/>
    <parent link="r_hip_pitch_link"/>
    <child link="r_knee_pitch_link"/>
    <axis xyz="0 0 1"/>
    <limit effort="1000" lower="-1.570796327" upper="1.570796327" velocity="3"/>
    <dynamics damping="0.5" friction="5"/>
  </joint>
  <transmission name="r_knee_pitch_joint_tran">
    <type>transmission_interface/SimpleTransmission</type>
    <joint name="r_knee_pitch_joint">
      <hardwareInterface>hardware_interface/EffortJointInterface</hardwareInterface>
    </joint>
    <actuator name="r_knee_pitch_joint_motor">
      <hardwareInterface>EffortJointInterface</hardwareInterface>
      <mechanicalReduction>1</mechanicalReduction>
    </actuator>
  </transmission>
  <!-- right knee pitch link -->
  <link name="r_knee_pitch_link">
    <visual>
      <origin rpy="0 0 0" xyz="0 0 0"/>
      <geometry>
        <mesh filename="package://huron_description/meshes/r_knee_pitch_link.STL" scale="1 1 1"/>
      </geometry>
      <material name="grey"/>
    </visual>
    <collision>
      <origin rpy="0 0 0" xyz="0 0 0"/>
      <geometry>
        <mesh filename="package://huron_description/meshes/r_knee_pitch_link.STL" scale="1 1 1"/>
      </geometry>
      <material name="grey"/>
    </collision>
    <inertial>
      <origin rpy="0 0 0" xyz="0.13396 0.00063335 -0.00486"/>
      <mass value="3.4875"/>
      <inertia ixx="0.0064812" ixy="1.2949E-05" ixz="2.8064E-05" iyy="0.019762" iyz="-1.0389E-05" izz="0.017354"/>
    </inertial>
  </link>
  <!-- right ankle pitch joint -->
  <joint name="r_ankle_pitch_joint" type="revolute">
    <origin rpy="0 0 0.0" xyz="0.370000000000006 -3.16358749707368E-05 -0.00249999999999943"/>
    <parent link="r_knee_pitch_link"/>
    <child link="r_ankle_pitch_link"/>
    <axis xyz="0 0 1"/>
    <limit effort="1000" lower="-0.5236" upper="0.1745" velocity="3"/>
    <dynamics damping="0.5" friction="2.0"/>
  </joint>
  <transmission name="r_ankle_pitch_joint_tran">
    <type>transmission_interface/SimpleTransmission</type>
    <joint name="r_ankle_pitch_joint">
      <hardwareInterface>hardware_interface/EffortJointInterface</hardwareInterface>
    </joint>
    <actuator name="r_ankle_pitch_joint_motor">
      <hardwareInterface>EffortJointInterface</hardwareInterface>
      <mechanicalReduction>1</mechanicalReduction>
    </actuator>
  </transmission>
  <!-- right ankle pitch link -->
  <link name="r_ankle_pitch_link">
    <visual>
      <origin rpy="0 0 0" xyz="0 0 0"/>
      <geometry>
        <mesh filename="package://huron_description/meshes/r_ankle_pitch_link.STL" scale="1 1 1"/>
      </geometry>
      <material name="">
        <color rgba="0.77647 0.75686 0.73725 1"/>
      </material>
    </visual>
    <collision>
      <origin rpy="0 0 0" xyz="0 0 0"/>
      <geometry>
        <mesh filename="package://huron_description/meshes/r_ankle_pitch_link.STL" scale="1 1 1"/>
      </geometry>
      <material name="">
        <color rgba="0.77647 0.75686 0.73725 1"/>
      </material>
    </collision>
    <inertial>
      <origin rpy="0 0 0" xyz="-0.029867 0.001045 0.000556"/>
      <mass value="2.4242"/>
      <inertia ixx="0.0025143" ixy="-0.00025651" ixz="1.5321E-12" iyy="0.0045125" iyz="9.9589E-10" izz="0.0049235"/>
    </inertial>
  </link>
  <!-- right ankle roll joint -->
  <joint name="r_ankle_roll_joint" type="revolute">
    <origin rpy="1.570796327 0 0" xyz="0 0 0"/>
    <parent link="r_ankle_pitch_link"/>
    <child link="r_ankle_roll_link"/>
    <axis xyz="0 0 1"/>
    <limit effort="1000" lower="-0.3491" upper="0.3491" velocity="3"/>
    <dynamics damping="0.5" friction="2.0"/>
  </joint>
  <transmission name="r_ankle_roll_joint_tran">
    <type>transmission_interface/SimpleTransmission</type>
    <joint name="r_ankle_roll_joint">
      <hardwareInterface>hardware_interface/EffortJointInterface</hardwareInterface>
    </joint>
    <actuator name="r_ankle_roll_joint_motor">
      <hardwareInterface>EffortJointInterface</hardwareInterface>
      <mechanicalReduction>1</mechanicalReduction>
    </actuator>
  </transmission>
  <!-- right ankle roll link -->
  <link name="r_ankle_roll_link">
    <visual>
      <origin rpy="0 0 0" xyz="0 0 0"/>
      <geometry>
        <mesh filename="package://huron_description/meshes/r_ankle_roll_link.STL" scale="1 1 1"/>
      </geometry>
      <material name="">
        <color rgba="0.77647 0.75686 0.73725 1"/>
      </material>
    </visual>
    <collision>
      <origin rpy="0 0 0" xyz="0 0 0"/>
      <geometry>
        <mesh filename="package://huron_description/meshes/r_ankle_roll_link.STL" scale="1 1 1"/>
      </geometry>
      <material name="">
        <color rgba="0.77647 0.75686 0.73725 1"/>
      </material>
    </collision>
    <inertial>
      <origin rpy="0 0 0" xyz="0.073422 7.2094E-05 0.063933"/>
      <mass value="1.8533"/>
      <inertia ixx="0.0086813" ixy="1.0356E-05" ixz="0.00024346" iyy="0.0084051" iyz="-0.00012301" izz="0.0013018"/>
    </inertial>
  </link>
  <!-- right ft fixed joint 1 -->
  <joint name="r1_ft_fixed" type="revolute">
    <origin rpy="-0.0095317 0.011124 1.5707" xyz="0.098271 0.014348 0.12788"/>
    <axis xyz="0 0 1"/>
    <parent link="r_ankle_roll_link"/>
    <child link="r1_foot_ft_link"/>
    <limit effort="100" lower="0" upper="0" velocity="100"/>
  </joint>
  <!-- right foot ft link 1 -->
  <link name="r1_foot_ft_link">
    <visual>
      <origin rpy=" 0 0 0" xyz="0 0 0"/>
      <geometry>
        <mesh filename="package://huron_description/meshes/r_foot_ft.STL" scale="1 1 1"/>
      </geometry>
      <material name="grey"/>
    </visual>
    <collision>
      <origin rpy=" 0 0 0" xyz="0 0 0"/>
      <geometry>
        <mesh filename="package://huron_description/meshes/r_foot_ft.STL" scale="1 1 1"/>
      </geometry>
      <material name="grey"/>
    </collision>
    <inertial>
      <origin rpy="0 0 0" xyz="-8.7899E-06 0.0048383 -9.7784E-08"/>
      <mass value="0.0086322"/>
      <inertia ixx="3.8994E-07" ixy="-3.4931E-10" ixz="5.2655E-10" iyy="5.8221E-07" iyz="-3.8859E-12" izz="3.4261E-07"/>
    </inertial>
  </link>
  <!-- right ft fixed joint 2 -->
  <joint name="r2_ft_fixed" type="revolute">
    <origin rpy="-0.0095317 0.011124 1.5707" xyz="0.098334 -0.020652 0.12788"/>
    <axis xyz="0 0 1"/>
    <parent link="r_ankle_roll_link"/>
    <child link="r2_foot_ft_link"/>
    <limit effort="100" lower="0" upper="0" velocity="100"/>
  </joint>
  <!-- right foot ft link 2 -->
  <link name="r2_foot_ft_link">
    <visual>
      <origin rpy=" 0 0 0" xyz="0 0 0"/>
      <geometry>
        <mesh filename="package://huron_description/meshes/r_foot_ft.STL" scale="1 1 1"/>
      </geometry>
      <material name="grey"/>
    </visual>
    <collision>
      <origin rpy=" 0 0 0" xyz="0 0 0"/>
      <geometry>
        <mesh filename="package://huron_description/meshes/r_foot_ft.STL" scale="1 1 1"/>
      </geometry>
      <material name="grey"/>
    </collision>
    <inertial>
      <origin rpy="0 0 0" xyz="-8.78991381628169E-06 0.00483832326857458 -9.77840948768183E-08"/>
      <mass value="0.00863223621815318"/>
      <inertia ixx="3.89936544476746E-07" ixy="-3.49305164752985E-10" ixz="5.26550951245735E-10" iyy="5.82213425821568E-07" iyz="-3.88587306925662E-12" izz="3.42610190440137E-07"/>
    </inertial>
  </link>
  <!-- right ft fixed joint 3 -->
  <joint name="r3_ft_fixed" type="revolute">
    <origin rpy="-0.0095317 0.011124 1.5707" xyz="0.098328 -0.01683 0"/>
    <axis xyz="0 0 1"/>
    <parent link="r_ankle_roll_link"/>
    <child link="r3_foot_ft_link"/>
    <limit effort="100" lower="0" upper="0" velocity="100"/>
  </joint>
  <!-- right foot ft link 3 -->
  <link name="r3_foot_ft_link">
    <visual>
      <origin rpy=" 0 0 0" xyz="0 0 0"/>
      <geometry>
        <mesh filename="package://huron_description/meshes/r_foot_ft.STL" scale="1 1 1"/>
      </geometry>
      <material name="grey"/>
    </visual>
    <collision>
      <origin rpy=" 0 0 0" xyz="0 0 0"/>
      <geometry>
        <mesh filename="package://huron_description/meshes/r_foot_ft.STL" scale="1 1 1"/>
      </geometry>
      <material name="grey"/>
    </collision>
    <inertial>
      <origin rpy="0 0 0" xyz="-8.78991381587924E-06 0.00483832326857436 -9.7784095154374E-08"/>
      <mass value="0.00863223621815318"/>
      <inertia ixx="3.89936544476746E-07" ixy="-3.49305164752997E-10" ixz="5.26550951245753E-10" iyy="5.82213425821568E-07" iyz="-3.88587306930208E-12" izz="3.42610190440137E-07"/>
    </inertial>
  </link>
  <!-- right ft fixed joint 4 -->
  <joint name="r4_ft_fixed" type="revolute">
    <origin rpy="-0.0095317 0.011124 1.5707" xyz="0.098267 0.016679 0"/>
    <axis xyz="0 0 1"/>
    <parent link="r_ankle_roll_link"/>
    <child link="r4_foot_ft_link"/>
    <limit effort="100" lower="0" upper="0" velocity="100"/>
  </joint>
  <!-- right4 foot ft link 4 -->
  <link name="r4_foot_ft_link">
    <visual>
      <origin rpy=" 0 0 0" xyz="0 0 0"/>
      <geometry>
        <mesh filename="package://huron_description/meshes/r_foot_ft.STL" scale="1 1 1"/>
      </geometry>
      <material name="grey"/>
    </visual>
    <collision>
      <origin rpy=" 0 0 0" xyz="0 0 0"/>
      <geometry>
        <mesh filename="package://huron_description/meshes/r_foot_ft.STL" scale="1 1 1"/>
      </geometry>
      <material name="grey"/>
    </collision>
    <inertial>
      <origin rpy="0 0 0" xyz="-8.78991381597638E-06 0.00483832326857403 -9.7784095154374E-08"/>
      <mass value="0.00863223621815318"/>
      <inertia ixx="3.89936544476746E-07" ixy="-3.49305164753006E-10" ixz="5.26550951245779E-10" iyy="5.82213425821568E-07" iyz="-3.88587306929652E-12" izz="3.42610190440137E-07"/>
    </inertial>
  </link>
  <!-- right ft fixed joint -->
  <joint name="rv_ft_fixed" type="fixed">
    <origin rpy="0 0 0" xyz="0.0 0.0 0.0"/>
    <axis xyz="0 0 0"/>
    <parent link="r4_foot_ft_link"/>
    <child link="r_foot_v_ft_link"/>
    <limit effort="100" lower="0" upper="0" velocity="100"/>
  </joint>
  <!-- right foot ft link -->
  <link name="r_foot_v_ft_link"/>
  <!-- Foot base -->
  <link name="r_foot_base_link">
    <visual>
      <origin rpy="0 0 0" xyz="0 0 0"/>
      <geometry>
        <box size="0.078 0.005 0.221"/>
      </geometry>
      <material name="green"/>
    </visual>
    <collision>
      <origin rpy="0 0 0" xyz="0 0 0"/>
      <geometry>
        <box size="0.078 0.005 0.221"/>
      </geometry>
      <material name="green"/>
    </collision>
    <inertial>
      <origin rpy="0 0 0" xyz="0 0 0"/>
      <mass value="0.01"/>
      <inertia ixx="2.162166667E-05" ixy="0" ixz="0" iyy="2.545416667E-05" iyz="0" izz="3.874166667E-06"/>
    </inertial>
  </link>
  <joint name="r_foot_base_fixed" type="fixed">
    <origin rpy="0 0 0" xyz="-0.0175 -0.0025 -0.06395"/>
    <parent link="r1_foot_ft_link"/>
    <child link="r_foot_base_link"/>
  </joint>
  <!-- left hip yaw joint -->
  <joint name="l_hip_yaw_joint" type="revolute">
    <origin rpy="0 0 -0.0" xyz="-0.0775 0 -0.14512"/>
    <parent link="base_footprint"/>
    <child link="l_hip_yaw_link"/>
    <axis xyz="0 0 1"/>
    <limit effort="1000" lower="-3.1416" upper="3.1416" velocity="3"/>
    <dynamics damping="0.5" friction="5"/>
  </joint>
  <transmission name="l_hip_yaw_joint_tran">
    <type>transmission_interface/SimpleTransmission</type>
    <joint name="l_hip_yaw_joint">
      <hardwareInterface>hardware_interface/EffortJointInterface</hardwareInterface>
    </joint>
    <actuator name="l_hip_yaw_joint_motor">
      <hardwareInterface>EffortJointInterface</hardwareInterface>
      <mechanicalReduction>1</mechanicalReduction>
    </actuator>
  </transmission>
  <!-- left hip yaw link -->
  <link name="l_hip_yaw_link">
    <visual>
      <origin rpy="0 0 0" xyz="0 0 0"/>
      <geometry>
        <mesh filename="package://huron_description/meshes/l_hip_yaw_link.STL" scale="1 1 1"/>
      </geometry>
      <material name="grey"/>
    </visual>
    <collision>
      <origin rpy="0 0 0" xyz="0 0 0"/>
      <geometry>
        <mesh filename="package://huron_description/meshes/l_hip_yaw_link.STL" scale="1 1 1"/>
      </geometry>
      <material name="grey"/>
    </collision>
    <inertial>
      <origin rpy="0 0 0" xyz="0.00063365 -0.00053469 0.063496"/>
      <mass value="1.6968"/>
      <inertia ixx="0.0022702" ixy="-2.5061E-10" ixz="6.6464E-06" iyy="0.0026746" iyz="-5.1468E-09" izz="0.001238"/>
    </inertial>
  </link>
  <!-- left hip roll joint-->
  <joint name="l_hip_roll_joint" type="revolute">
    <origin rpy="1.570796327 0 3.141592654" xyz="0 0 0"/>
    <parent link="l_hip_yaw_link"/>
    <child link="l_hip_roll_link"/>
    <axis xyz="0 0 1"/>
    <limit effort="1000" lower="-0.01" upper="0.5236" velocity="3"/>
    <dynamics damping="0.5" friction="5"/>
  </joint>
  <transmission name="l_hip_roll_joint_tran">
    <type>transmission_interface/SimpleTransmission</type>
    <joint name="l_hip_roll_joint">
      <hardwareInterface>hardware_interface/EffortJointInterface</hardwareInterface>
    </joint>
    <actuator name="l_hip_roll_joint_motor">
      <hardwareInterface>EffortJointInterface</hardwareInterface>
      <mechanicalReduction>1</mechanicalReduction>
    </actuator>
  </transmission>
  <!-- left hip roll link -->
  <link name="l_hip_roll_link">
    <visual>
      <origin rpy="0 0 0" xyz="0 0 0"/>
      <geometry>
        <mesh filename="package://huron_description/meshes/l_hip_roll_link.STL" scale="1 1 1"/>
      </geometry>
      <material name="grey"/>
    </visual>
    <collision>
      <origin rpy="0 0 0" xyz="0 0 0"/>
      <geometry>
        <mesh filename="package://huron_description/meshes/l_hip_roll_link.STL" scale="1 1 1"/>
      </geometry>
      <material name="grey"/>
    </collision>
    <inertial>
      <origin rpy="0 0 0" xyz="0.07196 0.0061153 -0.0005211"/>
      <mass value="1.1884"/>
      <inertia ixx="0.00098222" ixy="-9.9265E-08" ixz="4.9766E-09" iyy="0.00097045" iyz="-9.7282E-08" izz="0.00092365"/>
    </inertial>
  </link>
  <!-- left hip pitch joint -->
  <joint name="l_hip_pitch_joint" type="revolute">
    <origin rpy="-1.570796327 0 -1.570796327" xyz="0 0 0"/>
    <parent link="l_hip_roll_link"/>
    <child link="l_hip_pitch_link"/>
    <axis xyz="0 0 1"/>
    <limit effort="1000" lower="-1.2217" upper="1.2217" velocity="3"/>
    <dynamics damping="0.5" friction="5"/>
  </joint>
  <transmission name="l_hip_pitch_joint_tran">
    <type>transmission_interface/SimpleTransmission</type>
    <joint name="l_hip_pitch_joint">
      <hardwareInterface>hardware_interface/EffortJointInterface</hardwareInterface>
    </joint>
    <actuator name="l_hip_pitch_joint_motor">
      <hardwareInterface>EffortJointInterface</hardwareInterface>
      <mechanicalReduction>1</mechanicalReduction>
    </actuator>
  </transmission>
  <!-- left hip pitch link -->
  <link name="l_hip_pitch_link">
    <visual>
      <origin rpy="0 0 0" xyz="0 0 0"/>
      <geometry>
        <mesh filename="package://huron_description/meshes/l_hip_pitch_link.STL" scale="1 1 1"/>
      </geometry>
      <material name="grey"/>
    </visual>
    <collision>
      <origin rpy="0 0 0" xyz="0 0 0"/>
      <geometry>
        <mesh filename="package://huron_description/meshes/l_hip_pitch_link.STL" scale="1 1 1"/>
      </geometry>
      <material name="grey"/>
    </collision>
    <inertial>
      <origin rpy="0 0 0" xyz="0.26752 4.6211E-05 0.053152"/>
      <mass value="4.2544"/>
      <inertia ixx="0.0034527" ixy="-3.1056E-08" ixz="0.0019797" iyy="0.010032" iyz="-1.4618E-10" izz="0.01009"/>
    </inertial>
  </link>
  <!-- left knee pitch joint -->
  <joint name="l_knee_pitch_joint" type="revolute">
    <origin rpy="0 0 0" xyz="0.512778478308813 5.00027201116859E-05 1.66647320003488E-05"/>
    <parent link="l_hip_pitch_link"/>
    <child link="l_knee_pitch_link"/>
    <axis xyz="0 0 1"/>
    <limit effort="1000" lower="-1.570796327" upper="1.570796327" velocity="3"/>
    <dynamics damping="0.5" friction="5"/>
  </joint>
  <transmission name="l_knee_pitch_joint_tran">
    <type>transmission_interface/SimpleTransmission</type>
    <joint name="l_knee_pitch_joint">
      <hardwareInterface>hardware_interface/EffortJointInterface</hardwareInterface>
    </joint>
    <actuator name="l_knee_pitch_joint_motor">
      <hardwareInterface>EffortJointInterface</hardwareInterface>
      <mechanicalReduction>1</mechanicalReduction>
    </actuator>
  </transmission>
  <!-- left knee pitch link -->
  <link name="l_knee_pitch_link">
    <visual>
      <origin rpy="0 0 0" xyz="0 0 0"/>
      <geometry>
        <mesh filename="package://huron_description/meshes/l_knee_pitch_link.STL" scale="1 1 1"/>
      </geometry>
      <material name="grey"/>
    </visual>
    <collision>
      <origin rpy="0 0 0" xyz="0 0 0"/>
      <geometry>
        <mesh filename="package://huron_description/meshes/l_knee_pitch_link.STL" scale="1 1 1"/>
      </geometry>
      <material name="grey"/>
    </collision>
    <inertial>
      <origin rpy="0 0 0" xyz="0.13547 0.00068516 0.00486"/>
      <mass value="3.4875"/>
      <inertia ixx="0.0064814" ixy="1.2524E-05" ixz="-2.7966E-05" iyy="0.019762" iyz="1.0417E-05" izz="0.017354"/>
    </inertial>
  </link>
  <!-- left ankle pitch joint -->
  <joint name="l_ankle_pitch_joint" type="revolute">
    <origin rpy="0 0 0.0" xyz="0.3715 3.1633E-05 0.0025"/>
    <parent link="l_knee_pitch_link"/>
    <child link="l_ankle_pitch_link"/>
    <axis xyz="0 0 1"/>
    <limit effort="1000" lower="-0.5236" upper="0.1745" velocity="3"/>
    <dynamics damping="0.5" friction="2.0"/>
  </joint>
  <transmission name="l_ankle_pitch_joint_tran">
    <type>transmission_interface/SimpleTransmission</type>
    <joint name="l_ankle_pitch_joint">
      <hardwareInterface>hardware_interface/EffortJointInterface</hardwareInterface>
    </joint>
    <actuator name="l_ankle_pitch_joint_motor">
      <hardwareInterface>EffortJointInterface</hardwareInterface>
      <mechanicalReduction>1</mechanicalReduction>
    </actuator>
  </transmission>
  <!-- left ankle pitch link -->
  <link name="l_ankle_pitch_link">
    <visual>
      <origin rpy="0 0 0" xyz="0 0 0"/>
      <geometry>
        <mesh filename="package://huron_description/meshes/l_ankle_pitch_link.STL" scale="1 1 1"/>
      </geometry>
      <material name="">
        <color rgba="0.89804 0.91765 0.92941 1"/>
      </material>
    </visual>
    <collision>
      <origin rpy="0 0 0" xyz="0 0 0"/>
      <geometry>
        <mesh filename="package://huron_description/meshes/l_ankle_pitch_link.STL" scale="1 1 1"/>
      </geometry>
      <material name="">
        <color rgba="0.89804 0.91765 0.92941 1"/>
      </material>
    </collision>
    <inertial>
      <origin rpy="0 0 0" xyz="-0.029808 0.001045 3.1135E-08"/>
      <mass value="2.4242"/>
      <inertia ixx="0.0025143" ixy="-0.00025651" ixz="1.1633E-12" iyy="0.0045125" iyz="6.7196E-10" izz="0.0049235"/>
    </inertial>
  </link>
  <!-- left ankle roll pitch -->
  <joint name="l_ankle_roll_joint" type="revolute">
    <origin rpy="1.570796327 0 0" xyz="0 0 0"/>
    <parent link="l_ankle_pitch_link"/>
    <child link="l_ankle_roll_link"/>
    <axis xyz="0 0 1"/>
    <limit effort="1000" lower="-0.3491" upper="0.3491" velocity="3"/>
    <dynamics damping="0.5" friction="2.0"/>
  </joint>
  <transmission name="l_ankle_roll_joint_tran">
    <type>transmission_interface/SimpleTransmission</type>
    <joint name="l_ankle_roll_joint">
      <hardwareInterface>hardware_interface/EffortJointInterface</hardwareInterface>
    </joint>
    <actuator name="l_ankle_roll_joint_motor">
      <hardwareInterface>EffortJointInterface</hardwareInterface>
      <mechanicalReduction>1</mechanicalReduction>
    </actuator>
  </transmission>
  <!-- left ankle roll link -->
  <link name="l_ankle_roll_link">
    <visual>
      <origin rpy="0 0 0" xyz="0 0 0"/>
      <geometry>
        <mesh filename="package://huron_description/meshes/l_ankle_roll_link.STL" scale="1 1 1"/>
      </geometry>
      <material name="">
        <color rgba="0.77647 0.75686 0.73725 1"/>
      </material>
    </visual>
    <collision>
      <origin rpy="0 0 0" xyz="0 0 0"/>
      <geometry>
        <mesh filename="package://huron_description/meshes/l_ankle_roll_link.STL" scale="1 1 1"/>
      </geometry>
      <material name="">
        <color rgba="0.77647 0.75686 0.73725 1"/>
      </material>
    </collision>
    <inertial>
      <origin rpy="0 0 0" xyz="0.073422 -5.3261E-05 0.063946"/>
      <mass value="1.8533"/>
      <inertia ixx="0.008682" ixy="-1.0255E-05" ixz="0.00024351" iyy="0.0084057" iyz="0.00012332" izz="0.0013019"/>
    </inertial>
  </link>
  <!-- left ft fixed joint 1 -->
  <joint name="l1_ft_fixed" type="revolute">
    <origin rpy="-0.024938 0.00629 1.5706" xyz="0.098328 0.020682 0.12788"/>
    <axis xyz="0 0 1"/>
    <parent link="l_ankle_roll_link"/>
    <child link="l1_foot_ft_link"/>
    <limit effort="100" lower="0" upper="0" velocity="100"/>
  </joint>
  <!-- left foot ft link 1 -->
  <link name="l1_foot_ft_link">
    <visual>
      <origin rpy=" 0 0 0" xyz="0 0 0"/>
      <geometry>
        <mesh filename="package://huron_description/meshes/r_foot_ft.STL" scale="1 1 1"/>
      </geometry>
      <material name="green"/>
    </visual>
    <collision>
      <origin rpy=" 0 0 0" xyz="0 0 0"/>
      <geometry>
        <mesh filename="package://huron_description/meshes/r_foot_ft.STL" scale="1 1 1"/>
      </geometry>
      <material name="green"/>
    </collision>
    <inertial>
      <origin rpy="0 0 0" xyz="7.3272E-06 0.0048383 4.6103E-08"/>
      <mass value="0.0086322"/>
      <inertia ixx="3.8994E-07" ixy="2.9118E-10" ixz="2.9784E-10" iyy="5.8221E-07" iyz="1.8321E-12" izz="3.4261E-07"/>
    </inertial>
  </link>
  <!-- left ft fixed joint 2 -->
  <joint name="l2_ft_fixed" type="revolute">
    <origin rpy="-0.024938 0.00629 1.5706" xyz="0.098275 -0.014318 0.12788"/>
    <axis xyz="0 0 1"/>
    <parent link="l_ankle_roll_link"/>
    <child link="l2_foot_ft_link"/>
    <limit effort="100" lower="0" upper="0" velocity="100"/>
  </joint>
  <!-- left foot ft link 2 -->
  <link name="l2_foot_ft_link">
    <visual>
      <origin rpy=" 0 0 0" xyz="0 0 0"/>
      <geometry>
        <mesh filename="package://huron_description/meshes/r_foot_ft.STL" scale="1 1 1"/>
      </geometry>
      <material name="green"/>
    </visual>
    <collision>
      <origin rpy=" 0 0 0" xyz="0 0 0"/>
      <geometry>
        <mesh filename="package://huron_description/meshes/r_foot_ft.STL" scale="1 1 1"/>
      </geometry>
      <material name="green"/>
    </collision>
    <inertial>
      <origin rpy="0 0 0" xyz="7.32716003928879E-06 0.00483832570565201 4.61026197218217E-08"/>
      <mass value="0.00863223621815312"/>
      <inertia ixx="3.89940334430996E-07" ixy="2.91176476412897E-10" ixz="2.9783895900032E-10" iyy="5.82213619517231E-07" iyz="1.83208753538184E-12" izz="3.4260620679022E-07"/>
    </inertial>
  </link>
  <!-- left ft fixed joint 3 -->
  <joint name="l3_ft_fixed" type="revolute">
    <origin rpy="-0.024938 0.00629 1.5706" xyz="0.098272 -0.016649 0"/>
    <axis xyz="0 0 1"/>
    <parent link="l_ankle_roll_link"/>
    <child link="l3_foot_ft_link"/>
    <limit effort="100" lower="0" upper="0" velocity="100"/>
  </joint>
  <!-- left foot ft link 3 -->
  <link name="l3_foot_ft_link">
    <visual>
      <origin rpy=" 0 0 0" xyz="0 0 0"/>
      <geometry>
        <mesh filename="package://huron_description/meshes/r_foot_ft.STL" scale="1 1 1"/>
      </geometry>
      <material name="green"/>
    </visual>
    <collision>
      <origin rpy=" 0 0 0" xyz="0 0 0"/>
      <geometry>
        <mesh filename="package://huron_description/meshes/r_foot_ft.STL" scale="1 1 1"/>
      </geometry>
      <material name="green"/>
    </collision>
    <inertial>
      <origin rpy="0 0 0" xyz="7.32716003956635E-06 0.00483832570565224 4.61026188336433E-08"/>
      <mass value="0.00863223621815312"/>
      <inertia ixx="3.89940334430996E-07" ixy="2.9117647641293E-10" ixz="2.97838959000262E-10" iyy="5.82213619517231E-07" iyz="1.83208753540344E-12" izz="3.4260620679022E-07"/>
    </inertial>
  </link>
  <!-- left ft fixed joint 4 -->
  <joint name="l4_ft_fixed" type="revolute">
    <origin rpy="-0.024938 0.00629 1.5706" xyz="0.098322 0.01686 0"/>
    <axis xyz="0 0 1"/>
    <parent link="l_ankle_roll_link"/>
    <child link="l4_foot_ft_link"/>
    <limit effort="100" lower="0" upper="0" velocity="100"/>
  </joint>
  <!-- left foot ft link 4 -->
  <link name="l4_foot_ft_link">
    <visual>
      <origin rpy=" 0 0 0" xyz="0 0 0"/>
      <geometry>
        <mesh filename="package://huron_description/meshes/r_foot_ft.STL" scale="1 1 1"/>
      </geometry>
      <material name="green"/>
    </visual>
    <collision>
      <origin rpy=" 0 0 0" xyz="0 0 0"/>
      <geometry>
        <mesh filename="package://huron_description/meshes/r_foot_ft.STL" scale="1 1 1"/>
      </geometry>
      <material name="green"/>
    </collision>
    <inertial>
      <origin rpy="0 0 0" xyz="7.32716003670753E-06 0.00483832570565246 4.61026209985782E-08"/>
      <mass value="0.00863223621815312"/>
      <inertia ixx="3.89940334430996E-07" ixy="2.91176476412812E-10" ixz="2.97838959000613E-10" iyy="5.82213619517231E-07" iyz="1.83208753537968E-12" izz="3.42606206790219E-07"/>
    </inertial>
  </link>
  <!-- left ft fixed joint -->
  <joint name="lv_ft_fixed" type="fixed">
    <origin rpy="0 -1.570796327 0" xyz="0.045 0.0 0.0"/>
    <parent link="l4_foot_ft_link"/>
    <child link="l_foot_v_ft_link"/>
  </joint>
  <!-- left foot ft link -->
  <link name="l_foot_v_ft_link"/>
  <!-- Foot base -->
  <link name="l_foot_base_link">
    <visual>
      <origin rpy="0 0 0" xyz="0 0 0"/>
      <geometry>
        <box size="0.078 0.005 0.221"/>
      </geometry>
      <material name="green"/>
    </visual>
    <collision>
      <origin rpy="0 0 0" xyz="0 0 0"/>
      <geometry>
        <box size="0.078 0.005 0.221"/>
      </geometry>
      <material name="green"/>
    </collision>
    <inertial>
      <origin rpy="0 0 0" xyz="0 0 0"/>
      <mass value="0.01"/>
      <inertia ixx="2.162166667E-05" ixy="0" ixz="0" iyy="2.545416667E-05" iyz="0" izz="3.874166667E-06"/>
    </inertial>
  </link>
  <joint name="l_foot_base_fixed" type="fixed">
    <origin rpy="0 0 0" xyz="-0.0175 -0.0025 -0.06395"/>
    <parent link="l1_foot_ft_link"/>
    <child link="l_foot_base_link"/>
  </joint>
</robot>

